Workbook
Name headerRow: 'Structured 2025'!$1:$1
Name headerRow: 'Structured 2024'!$1:$1
Name headerRow2: 'Structured 2023'!$1:$1
Name oppCol: 'Structured 2025'!$C:$C
Name oppCol23: 'Structured 2023'!$C:$C
Name oppCol24: 'Structured 2024'!$C:$C
Name ovrHeaderRow: 'Overall 2024 Reference'!$1:$1
Name ovrHeaderRow2: 'Overall 2023 Reference'!$1:$1
Name ovrHeaderRow25: 'Overall 2025 Reference'!$1:$1
Name ovrTable: 'Overall 2024 Reference'!$A$1:$AH$69
Name ovrTable2: 'Overall 2023 Reference'!$A$1:$AJ$69
Name ovrTable25: 'Overall 2025 Reference'!$A$1:$AH$69
Name ovrTeamCol: 'Overall 2024 Reference'!$A:$A
Name ovrTeamCol2: 'Overall 2023 Reference'!$A:$A
Name ovrTeamCol25: 'Overall 2025 Reference'!$A:$A
Name rawLookup: 'Raw 2024 Season'!$B:$B
Name rawLookup2: 'Raw 2023 Season'!$B:$B
Name rawLookup25: 'Raw 2025 Season'!$B:$B
Name rawTeamCol: 'Raw 2024 Season'!$E:$E
Name rawTeamCol2: 'Raw 2023 Season'!$E:$E
Name rawTeamCol25: 'Raw 2025 Season'!$E:$E
Name rawValue: 'Raw 2024 Season'!$H:$H
Name rawValue2: 'Raw 2023 Season'!$H:$H
Name rawValue25: 'Raw 2025 Season'!$H:$H
Name statAbbr: mapping!$H:$H
Name statID: mapping!$J:$J
Name statOfficial: mapping!$I:$I
Name statsNames: [1]mapping!$K:$L
Name teamCol: 'Structured 2025'!$A:$A
Name teamCol: 'Structured 2024'!$A:$A
Name teamCol2: 'Structured 2023'!$A:$A
Name teamID: mapping!$D:$D
Name teamINI: mapping!$E:$E
Name teamRawName: mapping!$B:$B

Sheet Overall 2024 Reference
A1: Team | B1: Seed | C1: Games | D1: OPP | E1: 3PD% | F1: 3PPG | G1: 3PT% | H1: 3PTA | I1: A:T | J1: APG | K1: Bench | L1: BPG | M1: DFG% | N1: DRPG | O1: EFG% | P1: FB | Q1: FG% | R1: FPG | S1: FT% | T1: FTA | U1: FTPG | V1: OPPG | W1: ORPG | X1: PPG | Y1: RM | Z1: RPG | AA1: SM | AB1: SPG | AC1: TM | AD1: TOF | AE1: TPG | AF1: TEMPO | AG1: 2PT FGM | AH1: FGA
A2: CONN | B2: 1 | C2: 6 | D2: SEASON | E2: =INDEX(rawValue,MATCH(INDEX(teamID,MATCH(INDEX(ovrTeamCol,ROW(),1),teamINI,0))+INDEX(statID,MATCH(INDEX(ovrHeaderRow,1,COLUMN()),statAbbr,0),1),rawLookup,0)) -> 31.2 | F2: =INDEX(rawValue,MATCH(INDEX(teamID,MATCH(INDEX(ovrTeamCol,ROW(),1),teamINI,0))+INDEX(statID,MATCH(INDEX(ovrHeaderRow,1,COLUMN()),statAbbr,0),1),rawLookup,0)) -> 8.5 | G2: =INDEX(rawValue,MATCH(INDEX(teamID,MATCH(INDEX(ovrTeamCol,ROW(),1),teamINI,0))+INDEX(statID,MATCH(INDEX(ovrHeaderRow,1,COLUMN()),statAbbr,0),1),rawLookup,0)) -> 35.8 | H2: =INDEX(rawValue,MATCH(INDEX(teamID,MATCH(INDEX(ovrTeamCol,ROW(),1),teamINI,0))+INDEX(statID,MATCH(INDEX(ovrHeaderRow,1,COLUMN()),statAbbr,0),1),rawLookup,0)) -> 23.8 | I2: =INDEX(rawValue,MATCH(INDEX(teamID,MATCH(INDEX(ovrTeamCol,ROW(),1),teamINI,0))+INDEX(statID,MATCH(INDEX(ovrHeaderRow,1,COLUMN()),statAbbr,0),1),rawLookup,0)) -> 1.95 | J2: =INDEX(rawValue,MATCH(INDEX(teamID,MATCH(INDEX(ovrTeamCol,ROW(),1),teamINI,0))+INDEX(statID,MATCH(INDEX(ovrHeaderRow,1,COLUMN()),statAbbr,0),1),rawLookup,0)) -> 18.7 | K2: =INDEX(rawValue,MATCH(INDEX(teamID,MATCH(INDEX(ovrTeamCol,ROW(),1),teamINI,0))+INDEX(statID,MATCH(INDEX(ovrHeaderRow,1,COLUMN()),statAbbr,0),1),rawLookup,0)) -> 16.15 | L2: =INDEX(rawValue,MATCH(INDEX(teamID,MATCH(INDEX(ovrTeamCol,ROW(),1),teamINI,0))+INDEX(statID,MATCH(INDEX(ovrHeaderRow,1,COLUMN()),statAbbr,0),1),rawLookup,0)) -> 5.4 | ... AE2: =INDEX(rawValue,MATCH(INDEX(teamID,MATCH(INDEX(ovrTeamCol,ROW(),1),teamINI,0))+INDEX(statID,MATCH(INDEX(ovrHeaderRow,1,COLUMN()),statAbbr,0),1),rawLookup,0)) -> 9.6 | AF2: 67.9 | AG2: =(X2-U2-F2*3)/2 -> 20.9 | AH2: =(AG2+F2)*100/Q2 -> 59.15493
A3: PUR | B3: 1 | C3: 6 | D3: SEASON | E3: =INDEX(rawValue,MATCH(INDEX(teamID,MATCH(INDEX(ovrTeamCol,ROW(),1),teamINI,0))+INDEX(statID,MATCH(INDEX(ovrHeaderRow,1,COLUMN()),statAbbr,0),1),rawLookup,0)) -> 31.5 | F3: =INDEX(rawValue,MATCH(INDEX(teamID,MATCH(INDEX(ovrTeamCol,ROW(),1),teamINI,0))+INDEX(statID,MATCH(INDEX(ovrHeaderRow,1,COLUMN()),statAbbr,0),1),rawLookup,0)) -> 8.2 | G3: =INDEX(rawValue,MATCH(INDEX(teamID,MATCH(INDEX(ovrTeamCol,ROW(),1),teamINI,0))+INDEX(statID,MATCH(INDEX(ovrHeaderRow,1,COLUMN()),statAbbr,0),1),rawLookup,0)) -> 40.4 | H3: =INDEX(rawValue,MATCH(INDEX(teamID,MATCH(INDEX(ovrTeamCol,ROW(),1),teamINI,0))+INDEX(statID,MATCH(INDEX(ovrHeaderRow,1,COLUMN()),statAbbr,0),1),rawLookup,0)) -> 20.2 | I3: =INDEX(rawValue,MATCH(INDEX(teamID,MATCH(INDEX(ovrTeamCol,ROW(),1),teamINI,0))+INDEX(statID,MATCH(INDEX(ovrHeaderRow,1,COLUMN()),statAbbr,0),1),rawLookup,0)) -> 1.63 | J3: =INDEX(rawValue,MATCH(INDEX(teamID,MATCH(INDEX(ovrTeamCol,ROW(),1),teamINI,0))+INDEX(statID,MATCH(INDEX(ovrHeaderRow,1,COLUMN()),statAbbr,0),1),rawLookup,0)) -> 18.5 | K3: =INDEX(rawValue,MATCH(INDEX(teamID,MATCH(INDEX(ovrTeamCol,ROW(),1),teamINI,0))+INDEX(statID,MATCH(INDEX(ovrHeaderRow,1,COLUMN()),statAbbr,0),1),rawLookup,0)) -> 16.72 | L3: =INDEX(rawValue,MATCH(INDEX(teamID,MATCH(INDEX(ovrTeamCol,ROW(),1),teamINI,0))+INDEX(statID,MATCH(INDEX(ovrHeaderRow,1,COLUMN()),statAbbr,0),1),rawLookup,0)) -> 3.6 | ... AE3: =INDEX(rawValue,MATCH(INDEX(teamID,MATCH(INDEX(ovrTeamCol,ROW(),1),teamINI,0))+INDEX(statID,MATCH(INDEX(ovrHeaderRow,1,COLUMN()),statAbbr,0),1),rawLookup,0)) -> 11.3 | AF3: 70.1 | AG3: =(X3-U3-F3*3)/2 -> 20.2 | AH3: =(AG3+F3)*100/Q3 -> 58.196721
A4: ALA | B4: 4 | C4: 5 | D4: SEASON | E4: =INDEX(rawValue,MATCH(INDEX(teamID,MATCH(INDEX(ovrTeamCol,ROW(),1),teamINI,0))+INDEX(statID,MATCH(INDEX(ovrHeaderRow,1,COLUMN()),statAbbr,0),1),rawLookup,0)) -> 31.7 | F4: =INDEX(rawValue,MATCH(INDEX(teamID,MATCH(INDEX(ovrTeamCol,ROW(),1),teamINI,0))+INDEX(statID,MATCH(INDEX(ovrHeaderRow,1,COLUMN()),statAbbr,0),1),rawLookup,0)) -> 11.2 | G4: =INDEX(rawValue,MATCH(INDEX(teamID,MATCH(INDEX(ovrTeamCol,ROW(),1),teamINI,0))+INDEX(statID,MATCH(INDEX(ovrHeaderRow,1,COLUMN()),statAbbr,0),1),rawLookup,0)) -> 37.3 | H4: =INDEX(rawValue,MATCH(INDEX(teamID,MATCH(INDEX(ovrTeamCol,ROW(),1),teamINI,0))+INDEX(statID,MATCH(INDEX(ovrHeaderRow,1,COLUMN()),statAbbr,0),1),rawLookup,0)) -> 29.9 | I4: =INDEX(rawValue,MATCH(INDEX(teamID,MATCH(INDEX(ovrTeamCol,ROW(),1),teamINI,0))+INDEX(statID,MATCH(INDEX(ovrHeaderRow,1,COLUMN()),statAbbr,0),1),rawLookup,0)) -> 1.34 | J4: =INDEX(rawValue,MATCH(INDEX(teamID,MATCH(INDEX(ovrTeamCol,ROW(),1),teamINI,0))+INDEX(statID,MATCH(INDEX(ovrHeaderRow,1,COLUMN()),statAbbr,0),1),rawLookup,0)) -> 15.9 | K4: =INDEX(rawValue,MATCH(INDEX(teamID,MATCH(INDEX(ovrTeamCol,ROW(),1),teamINI,0))+INDEX(statID,MATCH(INDEX(ovrHeaderRow,1,COLUMN()),statAbbr,0),1),rawLookup,0)) -> 25.11 | L4: =INDEX(rawValue,MATCH(INDEX(teamID,MATCH(INDEX(ovrTeamCol,ROW(),1),teamINI,0))+INDEX(statID,MATCH(INDEX(ovrHeaderRow,1,COLUMN()),statAbbr,0),1),rawLookup,0)) -> 4.4 | ... AE4: =INDEX(rawValue,MATCH(INDEX(teamID,MATCH(INDEX(ovrTeamCol,ROW(),1),teamINI,0))+INDEX(statID,MATCH(INDEX(ovrHeaderRow,1,COLUMN()),statAbbr,0),1),rawLookup,0)) -> 11.8 | AF4: 76.3 | AG4: =(X4-U4-F4*3)/2 -> 19.45 | AH4: =(AG4+F4)*100/Q4 -> 64.390756
A5: NCSU | B5: 11 | C5: 5 | D5: SEASON | E5: =INDEX(rawValue,MATCH(INDEX(teamID,MATCH(INDEX(ovrTeamCol,ROW(),1),teamINI,0))+INDEX(statID,MATCH(INDEX(ovrHeaderRow,1,COLUMN()),statAbbr,0),1),rawLookup,0)) -> 33.5 | F5: =INDEX(rawValue,MATCH(INDEX(teamID,MATCH(INDEX(ovrTeamCol,ROW(),1),teamINI,0))+INDEX(statID,MATCH(INDEX(ovrHeaderRow,1,COLUMN()),statAbbr,0),1),rawLookup,0)) -> 7 | G5: =INDEX(rawValue,MATCH(INDEX(teamID,MATCH(INDEX(ovrTeamCol,ROW(),1),teamINI,0))+INDEX(statID,MATCH(INDEX(ovrHeaderRow,1,COLUMN()),statAbbr,0),1),rawLookup,0)) -> 34.5 | H5: =INDEX(rawValue,MATCH(INDEX(teamID,MATCH(INDEX(ovrTeamCol,ROW(),1),teamINI,0))+INDEX(statID,MATCH(INDEX(ovrHeaderRow,1,COLUMN()),statAbbr,0),1),rawLookup,0)) -> 20.2 | I5: =INDEX(rawValue,MATCH(INDEX(teamID,MATCH(INDEX(ovrTeamCol,ROW(),1),teamINI,0))+INDEX(statID,MATCH(INDEX(ovrHeaderRow,1,COLUMN()),statAbbr,0),1),rawLookup,0)) -> 1.37 | J5: =INDEX(rawValue,MATCH(INDEX(teamID,MATCH(INDEX(ovrTeamCol,ROW(),1),teamINI,0))+INDEX(statID,MATCH(INDEX(ovrHeaderRow,1,COLUMN()),statAbbr,0),1),rawLookup,0)) -> 13.1 | K5: =INDEX(rawValue,MATCH(INDEX(teamID,MATCH(INDEX(ovrTeamCol,ROW(),1),teamINI,0))+INDEX(statID,MATCH(INDEX(ovrHeaderRow,1,COLUMN()),statAbbr,0),1),rawLookup,0)) -> 18.8 | L5: =INDEX(rawValue,MATCH(INDEX(teamID,MATCH(INDEX(ovrTeamCol,ROW(),1),teamINI,0))+INDEX(statID,MATCH(INDEX(ovrHeaderRow,1,COLUMN()),statAbbr,0),1),rawLookup,0)) -> 3.6 | ... AE5: =INDEX(rawValue,MATCH(INDEX(teamID,MATCH(INDEX(ovrTeamCol,ROW(),1),teamINI,0))+INDEX(statID,MATCH(INDEX(ovrHeaderRow,1,COLUMN()),statAbbr,0),1),rawLookup,0)) -> 9.6 | AF5: 70.8 | AG5: =(X5-U5-F5*3)/2 -> 20.2 | AH5: =(AG5+F5)*100/Q5 -> 60.444444
A6: CLEM | B6: 6 | C6: 4 | D6: SEASON | E6: =INDEX(rawValue,MATCH(INDEX(teamID,MATCH(INDEX(ovrTeamCol,ROW(),1),teamINI,0))+INDEX(statID,MATCH(INDEX(ovrHeaderRow,1,COLUMN()),statAbbr,0),1),rawLookup,0)) -> 33.1 | F6: =INDEX(rawValue,MATCH(INDEX(teamID,MATCH(INDEX(ovrTeamCol,ROW(),1),teamINI,0))+INDEX(statID,MATCH(INDEX(ovrHeaderRow,1,COLUMN()),statAbbr,0),1),rawLookup,0)) -> 8.2 | G6: =INDEX(rawValue,MATCH(INDEX(teamID,MATCH(INDEX(ovrTeamCol,ROW(),1),teamINI,0))+INDEX(statID,MATCH(INDEX(ovrHeaderRow,1,COLUMN()),statAbbr,0),1),rawLookup,0)) -> 35.1 | H6: =INDEX(rawValue,MATCH(INDEX(teamID,MATCH(INDEX(ovrTeamCol,ROW(),1),teamINI,0))+INDEX(statID,MATCH(INDEX(ovrHeaderRow,1,COLUMN()),statAbbr,0),1),rawLookup,0)) -> 23.4 | I6: =INDEX(rawValue,MATCH(INDEX(teamID,MATCH(INDEX(ovrTeamCol,ROW(),1),teamINI,0))+INDEX(statID,MATCH(INDEX(ovrHeaderRow,1,COLUMN()),statAbbr,0),1),rawLookup,0)) -> 1.47 | J6: =INDEX(rawValue,MATCH(INDEX(teamID,MATCH(INDEX(ovrTeamCol,ROW(),1),teamINI,0))+INDEX(statID,MATCH(INDEX(ovrHeaderRow,1,COLUMN()),statAbbr,0),1),rawLookup,0)) -> 14.8 | K6: =INDEX(rawValue,MATCH(INDEX(teamID,MATCH(INDEX(ovrTeamCol,ROW(),1),teamINI,0))+INDEX(statID,MATCH(INDEX(ovrHeaderRow,1,COLUMN()),statAbbr,0),1),rawLookup,0)) -> 14.19 | L6: =INDEX(rawValue,MATCH(INDEX(teamID,MATCH(INDEX(ovrTeamCol,ROW(),1),teamINI,0))+INDEX(statID,MATCH(INDEX(ovrHeaderRow,1,COLUMN()),statAbbr,0),1),rawLookup,0)) -> 3.8 | ... AE6: =INDEX(rawValue,MATCH(INDEX(teamID,MATCH(INDEX(ovrTeamCol,ROW(),1),teamINI,0))+INDEX(statID,MATCH(INDEX(ovrHeaderRow,1,COLUMN()),statAbbr,0),1),rawLookup,0)) -> 10.1 | AF6: 69.7 | AG6: =(X6-U6-F6*3)/2 -> 19.35 | AH6: =(AG6+F6)*100/Q6 -> 58.742004
A7: DUKE | B7: 4 | C7: 4 | D7: SEASON | E7: =INDEX(rawValue,MATCH(INDEX(teamID,MATCH(INDEX(ovrTeamCol,ROW(),1),teamINI,0))+INDEX(statID,MATCH(INDEX(ovrHeaderRow,1,COLUMN()),statAbbr,0),1),rawLookup,0)) -> 31.8 | F7: =INDEX(rawValue,MATCH(INDEX(teamID,MATCH(INDEX(ovrTeamCol,ROW(),1),teamINI,0))+INDEX(statID,MATCH(INDEX(ovrHeaderRow,1,COLUMN()),statAbbr,0),1),rawLookup,0)) -> 8.3 | G7: =INDEX(rawValue,MATCH(INDEX(teamID,MATCH(INDEX(ovrTeamCol,ROW(),1),teamINI,0))+INDEX(statID,MATCH(INDEX(ovrHeaderRow,1,COLUMN()),statAbbr,0),1),rawLookup,0)) -> 37.7 | H7: =INDEX(rawValue,MATCH(INDEX(teamID,MATCH(INDEX(ovrTeamCol,ROW(),1),teamINI,0))+INDEX(statID,MATCH(INDEX(ovrHeaderRow,1,COLUMN()),statAbbr,0),1),rawLookup,0)) -> 22 | I7: =INDEX(rawValue,MATCH(INDEX(teamID,MATCH(INDEX(ovrTeamCol,ROW(),1),teamINI,0))+INDEX(statID,MATCH(INDEX(ovrHeaderRow,1,COLUMN()),statAbbr,0),1),rawLookup,0)) -> 1.58 | J7: =INDEX(rawValue,MATCH(INDEX(teamID,MATCH(INDEX(ovrTeamCol,ROW(),1),teamINI,0))+INDEX(statID,MATCH(INDEX(ovrHeaderRow,1,COLUMN()),statAbbr,0),1),rawLookup,0)) -> 15.3 | K7: =INDEX(rawValue,MATCH(INDEX(teamID,MATCH(INDEX(ovrTeamCol,ROW(),1),teamINI,0))+INDEX(statID,MATCH(INDEX(ovrHeaderRow,1,COLUMN()),statAbbr,0),1),rawLookup,0)) -> 14.22 | L7: =INDEX(rawValue,MATCH(INDEX(teamID,MATCH(INDEX(ovrTeamCol,ROW(),1),teamINI,0))+INDEX(statID,MATCH(INDEX(ovrHeaderRow,1,COLUMN()),statAbbr,0),1),rawLookup,0)) -> 3.7 | ... AE7: =INDEX(rawValue,MATCH(INDEX(teamID,MATCH(INDEX(ovrTeamCol,ROW(),1),teamINI,0))+INDEX(statID,MATCH(INDEX(ovrHeaderRow,1,COLUMN()),statAbbr,0),1),rawLookup,0)) -> 9.7 | AF7: 68.6 | AG7: =(X7-U7-F7*3)/2 -> 19.55 | AH7: =(AG7+F7)*100/Q7 -> 58.631579
A8: ILL | B8: 3 | C8: 4 | D8: SEASON | E8: =INDEX(rawValue,MATCH(INDEX(teamID,MATCH(INDEX(ovrTeamCol,ROW(),1),teamINI,0))+INDEX(statID,MATCH(INDEX(ovrHeaderRow,1,COLUMN()),statAbbr,0),1),rawLookup,0)) -> 34.1 | F8: =INDEX(rawValue,MATCH(INDEX(teamID,MATCH(INDEX(ovrTeamCol,ROW(),1),teamINI,0))+INDEX(statID,MATCH(INDEX(ovrHeaderRow,1,COLUMN()),statAbbr,0),1),rawLookup,0)) -> 8.3 | G8: =INDEX(rawValue,MATCH(INDEX(teamID,MATCH(INDEX(ovrTeamCol,ROW(),1),teamINI,0))+INDEX(statID,MATCH(INDEX(ovrHeaderRow,1,COLUMN()),statAbbr,0),1),rawLookup,0)) -> 34.9 | H8: =INDEX(rawValue,MATCH(INDEX(teamID,MATCH(INDEX(ovrTeamCol,ROW(),1),teamINI,0))+INDEX(statID,MATCH(INDEX(ovrHeaderRow,1,COLUMN()),statAbbr,0),1),rawLookup,0)) -> 23.9 | I8: =INDEX(rawValue,MATCH(INDEX(teamID,MATCH(INDEX(ovrTeamCol,ROW(),1),teamINI,0))+INDEX(statID,MATCH(INDEX(ovrHeaderRow,1,COLUMN()),statAbbr,0),1),rawLookup,0)) -> 1.26 | J8: =INDEX(rawValue,MATCH(INDEX(teamID,MATCH(INDEX(ovrTeamCol,ROW(),1),teamINI,0))+INDEX(statID,MATCH(INDEX(ovrHeaderRow,1,COLUMN()),statAbbr,0),1),rawLookup,0)) -> 13.3 | K8: =INDEX(rawValue,MATCH(INDEX(teamID,MATCH(INDEX(ovrTeamCol,ROW(),1),teamINI,0))+INDEX(statID,MATCH(INDEX(ovrHeaderRow,1,COLUMN()),statAbbr,0),1),rawLookup,0)) -> 19.18 | L8: =INDEX(rawValue,MATCH(INDEX(teamID,MATCH(INDEX(ovrTeamCol,ROW(),1),teamINI,0))+INDEX(statID,MATCH(INDEX(ovrHeaderRow,1,COLUMN()),statAbbr,0),1),rawLookup,0)) -> 3.8 | ... AE8: =INDEX(rawValue,MATCH(INDEX(teamID,MATCH(INDEX(ovrTeamCol,ROW(),1),teamINI,0))+INDEX(statID,MATCH(INDEX(ovrHeaderRow,1,COLUMN()),statAbbr,0),1),rawLookup,0)) -> 10.6 | AF8: 72.3 | AG8: =(X8-U8-F8*3)/2 -> 20.8 | AH8: =(AG8+F8)*100/Q8 -> 62.046908
A9: TENN | B9: 2 | C9: 4 | D9: SEASON | E9: =INDEX(rawValue,MATCH(INDEX(teamID,MATCH(INDEX(ovrTeamCol,ROW(),1),teamINI,0))+INDEX(statID,MATCH(INDEX(ovrHeaderRow,1,COLUMN()),statAbbr,0),1),rawLookup,0)) -> 31.2 | F9: =INDEX(rawValue,MATCH(INDEX(teamID,MATCH(INDEX(ovrTeamCol,ROW(),1),teamINI,0))+INDEX(statID,MATCH(INDEX(ovrHeaderRow,1,COLUMN()),statAbbr,0),1),rawLookup,0)) -> 8.8 | G9: =INDEX(rawValue,MATCH(INDEX(teamID,MATCH(INDEX(ovrTeamCol,ROW(),1),teamINI,0))+INDEX(statID,MATCH(INDEX(ovrHeaderRow,1,COLUMN()),statAbbr,0),1),rawLookup,0)) -> 34.4 | H9: =INDEX(rawValue,MATCH(INDEX(teamID,MATCH(INDEX(ovrTeamCol,ROW(),1),teamINI,0))+INDEX(statID,MATCH(INDEX(ovrHeaderRow,1,COLUMN()),statAbbr,0),1),rawLookup,0)) -> 25.4 | I9: =INDEX(rawValue,MATCH(INDEX(teamID,MATCH(INDEX(ovrTeamCol,ROW(),1),teamINI,0))+INDEX(statID,MATCH(INDEX(ovrHeaderRow,1,COLUMN()),statAbbr,0),1),rawLookup,0)) -> 1.63 | J9: =INDEX(rawValue,MATCH(INDEX(teamID,MATCH(INDEX(ovrTeamCol,ROW(),1),teamINI,0))+INDEX(statID,MATCH(INDEX(ovrHeaderRow,1,COLUMN()),statAbbr,0),1),rawLookup,0)) -> 16.7 | K9: =INDEX(rawValue,MATCH(INDEX(teamID,MATCH(INDEX(ovrTeamCol,ROW(),1),teamINI,0))+INDEX(statID,MATCH(INDEX(ovrHeaderRow,1,COLUMN()),statAbbr,0),1),rawLookup,0)) -> 18.86 | L9: =INDEX(rawValue,MATCH(INDEX(teamID,MATCH(INDEX(ovrTeamCol,ROW(),1),teamINI,0))+INDEX(statID,MATCH(INDEX(ovrHeaderRow,1,COLUMN()),statAbbr,0),1),rawLookup,0)) -> 4.6 | ... AE9: =INDEX(rawValue,MATCH(INDEX(teamID,MATCH(INDEX(ovrTeamCol,ROW(),1),teamINI,0))+INDEX(statID,MATCH(INDEX(ovrHeaderRow,1,COLUMN()),statAbbr,0),1),rawLookup,0)) -> 10.2 | AF9: 71.6 | AG9: =(X9-U9-F9*3)/2 -> 18.4 | AH9: =(AG9+F9)*100/Q9 -> 61.818182
A10: ARIZ | B10: 2 | C10: 3 | D10: SEASON | E10: =INDEX(rawValue,MATCH(INDEX(teamID,MATCH(INDEX(ovrTeamCol,ROW(),1),teamINI,0))+INDEX(statID,MATCH(INDEX(ovrHeaderRow,1,COLUMN()),statAbbr,0),1),rawLookup,0)) -> 32.9 | F10: =INDEX(rawValue,MATCH(INDEX(teamID,MATCH(INDEX(ovrTeamCol,ROW(),1),teamINI,0))+INDEX(statID,MATCH(INDEX(ovrHeaderRow,1,COLUMN()),statAbbr,0),1),rawLookup,0)) -> 7.9 | G10: =INDEX(rawValue,MATCH(INDEX(teamID,MATCH(INDEX(ovrTeamCol,ROW(),1),teamINI,0))+INDEX(statID,MATCH(INDEX(ovrHeaderRow,1,COLUMN()),statAbbr,0),1),rawLookup,0)) -> 36.6 | H10: =INDEX(rawValue,MATCH(INDEX(teamID,MATCH(INDEX(ovrTeamCol,ROW(),1),teamINI,0))+INDEX(statID,MATCH(INDEX(ovrHeaderRow,1,COLUMN()),statAbbr,0),1),rawLookup,0)) -> 21.6 | I10: =INDEX(rawValue,MATCH(INDEX(teamID,MATCH(INDEX(ovrTeamCol,ROW(),1),teamINI,0))+INDEX(statID,MATCH(INDEX(ovrHeaderRow,1,COLUMN()),statAbbr,0),1),rawLookup,0)) -> 1.55 | J10: =INDEX(rawValue,MATCH(INDEX(teamID,MATCH(INDEX(ovrTeamCol,ROW(),1),teamINI,0))+INDEX(statID,MATCH(INDEX(ovrHeaderRow,1,COLUMN()),statAbbr,0),1),rawLookup,0)) -> 18.5 | K10: =INDEX(rawValue,MATCH(INDEX(teamID,MATCH(INDEX(ovrTeamCol,ROW(),1),teamINI,0))+INDEX(statID,MATCH(INDEX(ovrHeaderRow,1,COLUMN()),statAbbr,0),1),rawLookup,0)) -> 22.86 | L10: =INDEX(rawValue,MATCH(INDEX(teamID,MATCH(INDEX(ovrTeamCol,ROW(),1),teamINI,0))+INDEX(statID,MATCH(INDEX(ovrHeaderRow,1,COLUMN()),statAbbr,0),1),rawLookup,0)) -> 3.7 | ... AE10: =INDEX(rawValue,MATCH(INDEX(teamID,MATCH(INDEX(ovrTeamCol,ROW(),1),teamINI,0))+INDEX(statID,MATCH(INDEX(ovrHeaderRow,1,COLUMN()),statAbbr,0),1),rawLookup,0)) -> 11.9 | AF10: 76.3 | AG10: =(X10-U10-F10*3)/2 -> 23.3 | AH10: =(AG10+F10)*100/Q10 -> 64.46281
A11: COLO | B11: 10 | C11: 3 | D11: SEASON | E11: =INDEX(rawValue,MATCH(INDEX(teamID,MATCH(INDEX(ovrTeamCol,ROW(),1),teamINI,0))+INDEX(statID,MATCH(INDEX(ovrHeaderRow,1,COLUMN()),statAbbr,0),1),rawLookup,0)) -> 32 | F11: =INDEX(rawValue,MATCH(INDEX(teamID,MATCH(INDEX(ovrTeamCol,ROW(),1),teamINI,0))+INDEX(statID,MATCH(INDEX(ovrHeaderRow,1,COLUMN()),statAbbr,0),1),rawLookup,0)) -> 6.9 | G11: =INDEX(rawValue,MATCH(INDEX(teamID,MATCH(INDEX(ovrTeamCol,ROW(),1),teamINI,0))+INDEX(statID,MATCH(INDEX(ovrHeaderRow,1,COLUMN()),statAbbr,0),1),rawLookup,0)) -> 39.1 | H11: =INDEX(rawValue,MATCH(INDEX(teamID,MATCH(INDEX(ovrTeamCol,ROW(),1),teamINI,0))+INDEX(statID,MATCH(INDEX(ovrHeaderRow,1,COLUMN()),statAbbr,0),1),rawLookup,0)) -> 17.5 | I11: =INDEX(rawValue,MATCH(INDEX(teamID,MATCH(INDEX(ovrTeamCol,ROW(),1),teamINI,0))+INDEX(statID,MATCH(INDEX(ovrHeaderRow,1,COLUMN()),statAbbr,0),1),rawLookup,0)) -> 1.28 | J11: =INDEX(rawValue,MATCH(INDEX(teamID,MATCH(INDEX(ovrTeamCol,ROW(),1),teamINI,0))+INDEX(statID,MATCH(INDEX(ovrHeaderRow,1,COLUMN()),statAbbr,0),1),rawLookup,0)) -> 16.2 | K11: =INDEX(rawValue,MATCH(INDEX(teamID,MATCH(INDEX(ovrTeamCol,ROW(),1),teamINI,0))+INDEX(statID,MATCH(INDEX(ovrHeaderRow,1,COLUMN()),statAbbr,0),1),rawLookup,0)) -> 11.27 | L11: =INDEX(rawValue,MATCH(INDEX(teamID,MATCH(INDEX(ovrTeamCol,ROW(),1),teamINI,0))+INDEX(statID,MATCH(INDEX(ovrHeaderRow,1,COLUMN()),statAbbr,0),1),rawLookup,0)) -> 2.2 | ... AE11: =INDEX(rawValue,MATCH(INDEX(teamID,MATCH(INDEX(ovrTeamCol,ROW(),1),teamINI,0))+INDEX(statID,MATCH(INDEX(ovrHeaderRow,1,COLUMN()),statAbbr,0),1),rawLookup,0)) -> 12.6 | AF11: 71.3 | AG11: =(X11-U11-F11*3)/2 -> 21.4 | AH11: =(AG11+F11)*100/Q11 -> 57.171717
A12: CREI | B12: 3 | C12: 3 | D12: SEASON | E12: =INDEX(rawValue,MATCH(INDEX(teamID,MATCH(INDEX(ovrTeamCol,ROW(),1),teamINI,0))+INDEX(statID,MATCH(INDEX(ovrHeaderRow,1,COLUMN()),statAbbr,0),1),rawLookup,0)) -> 32.3 | F12: =INDEX(rawValue,MATCH(INDEX(teamID,MATCH(INDEX(ovrTeamCol,ROW(),1),teamINI,0))+INDEX(statID,MATCH(INDEX(ovrHeaderRow,1,COLUMN()),statAbbr,0),1),rawLookup,0)) -> 10.7 | G12: =INDEX(rawValue,MATCH(INDEX(teamID,MATCH(INDEX(ovrTeamCol,ROW(),1),teamINI,0))+INDEX(statID,MATCH(INDEX(ovrHeaderRow,1,COLUMN()),statAbbr,0),1),rawLookup,0)) -> 36.8 | H12: =INDEX(rawValue,MATCH(INDEX(teamID,MATCH(INDEX(ovrTeamCol,ROW(),1),teamINI,0))+INDEX(statID,MATCH(INDEX(ovrHeaderRow,1,COLUMN()),statAbbr,0),1),rawLookup,0)) -> 29.1 | I12: =INDEX(rawValue,MATCH(INDEX(teamID,MATCH(INDEX(ovrTeamCol,ROW(),1),teamINI,0))+INDEX(statID,MATCH(INDEX(ovrHeaderRow,1,COLUMN()),statAbbr,0),1),rawLookup,0)) -> 1.58 | J12: =INDEX(rawValue,MATCH(INDEX(teamID,MATCH(INDEX(ovrTeamCol,ROW(),1),teamINI,0))+INDEX(statID,MATCH(INDEX(ovrHeaderRow,1,COLUMN()),statAbbr,0),1),rawLookup,0)) -> 16.8 | K12: =INDEX(rawValue,MATCH(INDEX(teamID,MATCH(INDEX(ovrTeamCol,ROW(),1),teamINI,0))+INDEX(statID,MATCH(INDEX(ovrHeaderRow,1,COLUMN()),statAbbr,0),1),rawLookup,0)) -> 10.49 | L12: =INDEX(rawValue,MATCH(INDEX(teamID,MATCH(INDEX(ovrTeamCol,ROW(),1),teamINI,0))+INDEX(statID,MATCH(INDEX(ovrHeaderRow,1,COLUMN()),statAbbr,0),1),rawLookup,0)) -> 4.1 | ... AE12: =INDEX(rawValue,MATCH(INDEX(teamID,MATCH(INDEX(ovrTeamCol,ROW(),1),teamINI,0))+INDEX(statID,MATCH(INDEX(ovrHeaderRow,1,COLUMN()),statAbbr,0),1),rawLookup,0)) -> 10.6 | AF12: 70.5 | AG12: =(X12-U12-F12*3)/2 -> 18.3 | AH12: =(AG12+F12)*100/Q12 -> 59.917355
A13: GONZ | B13: 5 | C13: 3 | D13: SEASON | E13: =INDEX(rawValue,MATCH(INDEX(teamID,MATCH(INDEX(ovrTeamCol,ROW(),1),teamINI,0))+INDEX(statID,MATCH(INDEX(ovrHeaderRow,1,COLUMN()),statAbbr,0),1),rawLookup,0)) -> 33.6 | F13: =INDEX(rawValue,MATCH(INDEX(teamID,MATCH(INDEX(ovrTeamCol,ROW(),1),teamINI,0))+INDEX(statID,MATCH(INDEX(ovrHeaderRow,1,COLUMN()),statAbbr,0),1),rawLookup,0)) -> 6.9 | G13: =INDEX(rawValue,MATCH(INDEX(teamID,MATCH(INDEX(ovrTeamCol,ROW(),1),teamINI,0))+INDEX(statID,MATCH(INDEX(ovrHeaderRow,1,COLUMN()),statAbbr,0),1),rawLookup,0)) -> 36.1 | H13: =INDEX(rawValue,MATCH(INDEX(teamID,MATCH(INDEX(ovrTeamCol,ROW(),1),teamINI,0))+INDEX(statID,MATCH(INDEX(ovrHeaderRow,1,COLUMN()),statAbbr,0),1),rawLookup,0)) -> 19.3 | I13: =INDEX(rawValue,MATCH(INDEX(teamID,MATCH(INDEX(ovrTeamCol,ROW(),1),teamINI,0))+INDEX(statID,MATCH(INDEX(ovrHeaderRow,1,COLUMN()),statAbbr,0),1),rawLookup,0)) -> 1.71 | J13: =INDEX(rawValue,MATCH(INDEX(teamID,MATCH(INDEX(ovrTeamCol,ROW(),1),teamINI,0))+INDEX(statID,MATCH(INDEX(ovrHeaderRow,1,COLUMN()),statAbbr,0),1),rawLookup,0)) -> 16.7 | K13: =INDEX(rawValue,MATCH(INDEX(teamID,MATCH(INDEX(ovrTeamCol,ROW(),1),teamINI,0))+INDEX(statID,MATCH(INDEX(ovrHeaderRow,1,COLUMN()),statAbbr,0),1),rawLookup,0)) -> 18.71 | L13: =INDEX(rawValue,MATCH(INDEX(teamID,MATCH(INDEX(ovrTeamCol,ROW(),1),teamINI,0))+INDEX(statID,MATCH(INDEX(ovrHeaderRow,1,COLUMN()),statAbbr,0),1),rawLookup,0)) -> 3.9 | ... AE13: =INDEX(rawValue,MATCH(INDEX(teamID,MATCH(INDEX(ovrTeamCol,ROW(),1),teamINI,0))+INDEX(statID,MATCH(INDEX(ovrHeaderRow,1,COLUMN()),statAbbr,0),1),rawLookup,0)) -> 9.8 | AF13: 70.7 | AG13: =(X13-U13-F13*3)/2 -> 25.1 | AH13: =(AG13+F13)*100/Q13 -> 61.776062
... A69: WKU | B69: 15 | C69: 1 | D69: SEASON | E69: =INDEX(rawValue,MATCH(INDEX(teamID,MATCH(INDEX(ovrTeamCol,ROW(),1),teamINI,0))+INDEX(statID,MATCH(INDEX(ovrHeaderRow,1,COLUMN()),statAbbr,0),1),rawLookup,0)) -> 31.8 | F69: =INDEX(rawValue,MATCH(INDEX(teamID,MATCH(INDEX(ovrTeamCol,ROW(),1),teamINI,0))+INDEX(statID,MATCH(INDEX(ovrHeaderRow,1,COLUMN()),statAbbr,0),1),rawLookup,0)) -> 6.9 | G69: =INDEX(rawValue,MATCH(INDEX(teamID,MATCH(INDEX(ovrTeamCol,ROW(),1),teamINI,0))+INDEX(statID,MATCH(INDEX(ovrHeaderRow,1,COLUMN()),statAbbr,0),1),rawLookup,0)) -> 34 | H69: =INDEX(rawValue,MATCH(INDEX(teamID,MATCH(INDEX(ovrTeamCol,ROW(),1),teamINI,0))+INDEX(statID,MATCH(INDEX(ovrHeaderRow,1,COLUMN()),statAbbr,0),1),rawLookup,0)) -> 20.2 | I69: =INDEX(rawValue,MATCH(INDEX(teamID,MATCH(INDEX(ovrTeamCol,ROW(),1),teamINI,0))+INDEX(statID,MATCH(INDEX(ovrHeaderRow,1,COLUMN()),statAbbr,0),1),rawLookup,0)) -> 0.97 | J69: =INDEX(rawValue,MATCH(INDEX(teamID,MATCH(INDEX(ovrTeamCol,ROW(),1),teamINI,0))+INDEX(statID,MATCH(INDEX(ovrHeaderRow,1,COLUMN()),statAbbr,0),1),rawLookup,0)) -> 13.4 | K69: =INDEX(rawValue,MATCH(INDEX(teamID,MATCH(INDEX(ovrTeamCol,ROW(),1),teamINI,0))+INDEX(statID,MATCH(INDEX(ovrHeaderRow,1,COLUMN()),statAbbr,0),1),rawLookup,0)) -> 28.79 | L69: =INDEX(rawValue,MATCH(INDEX(teamID,MATCH(INDEX(ovrTeamCol,ROW(),1),teamINI,0))+INDEX(statID,MATCH(INDEX(ovrHeaderRow,1,COLUMN()),statAbbr,0),1),rawLookup,0)) -> 3.2 | ... AE69: =INDEX(rawValue,MATCH(INDEX(teamID,MATCH(INDEX(ovrTeamCol,ROW(),1),teamINI,0))+INDEX(statID,MATCH(INDEX(ovrHeaderRow,1,COLUMN()),statAbbr,0),1),rawLookup,0)) -> 13.8 | AF69: 77.2 | AG69: =(X69-U69-F69*3)/2 -> 22.35 | AH69: =(AG69+F69)*100/Q69 -> 62.76824

Sheet Raw 2024 Season
A2: =IF(NOT(D2=""),INDEX(statAbbr,MATCH(D2,statOfficial,0),1),A1) -> #N/A | B2: =INDEX(statID,MATCH(A2,statAbbr,0),1)+INDEX(teamID,MATCH(E2,teamRawName,0)) -> #N/A | D2: Statistic | E2: Team | F2: National | G2: Conference | H2: Value | I2: National Leader | J2: Value
A3: =IF(NOT(D3=""),INDEX(statAbbr,MATCH(D3,statOfficial,0),1),A2) -> #N/A | B3: =INDEX(statID,MATCH(A3,statAbbr,0),1)+INDEX(teamID,MATCH(E3,teamRawName,0)) -> #N/A | F3: Rank | G3: Rank
A4: =IF(NOT(D4=""),INDEX(statAbbr,MATCH(D4,statOfficial,0),1),A3) -> A:T | B4: =INDEX(statID,MATCH(A4,statAbbr,0),1)+INDEX(teamID,MATCH(E4,teamRawName,0)) -> 2305 | D4: Assist/Turnover Ratio (351 ranked) | E4: UConn | F4: 1 | G4: 1 | H4: 1.95 | I4: UConn | J4: 1.95
A5: =IF(NOT(D5=""),INDEX(statAbbr,MATCH(D5,statOfficial,0),1),A4) -> A:T | B5: =INDEX(statID,MATCH(A5,statAbbr,0),1)+INDEX(teamID,MATCH(E5,teamRawName,0)) -> 2605 | E5: Virginia | F5: 2 | G5: 1 | H5: 1.86
A6: =IF(NOT(D6=""),INDEX(statAbbr,MATCH(D6,statOfficial,0),1),A5) -> A:T | B6: =INDEX(statID,MATCH(A6,statAbbr,0),1)+INDEX(teamID,MATCH(E6,teamRawName,0)) -> 6205 | E6: Northwestern | F6: 5 | G6: 2 | H6: 1.77
A7: =IF(NOT(D7=""),INDEX(statAbbr,MATCH(D7,statOfficial,0),1),A6) -> A:T | B7: =INDEX(statID,MATCH(A7,statAbbr,0),1)+INDEX(teamID,MATCH(E7,teamRawName,0)) -> 2705 | E7: BYU | F7: 6 | G7: 1 | H7: 1.73
A8: =IF(NOT(D8=""),INDEX(statAbbr,MATCH(D8,statOfficial,0),1),A7) -> A:T | B8: =INDEX(statID,MATCH(A8,statAbbr,0),1)+INDEX(teamID,MATCH(E8,teamRawName,0)) -> 1305 | E8: Colorado St. | F8: 7 | G8: 1 | H8: 1.72
A9: =IF(NOT(D9=""),INDEX(statAbbr,MATCH(D9,statOfficial,0),1),A8) -> A:T | B9: =INDEX(statID,MATCH(A9,statAbbr,0),1)+INDEX(teamID,MATCH(E9,teamRawName,0)) -> 4405 | E9: Gonzaga | F9: 8 | G9: 1 | H9: 1.71
A10: =IF(NOT(D10=""),INDEX(statAbbr,MATCH(D10,statOfficial,0),1),A9) -> A:T | B10: =INDEX(statID,MATCH(A10,statAbbr,0),1)+INDEX(teamID,MATCH(E10,teamRawName,0)) -> 4505 | E10: Auburn | F10: 9 | G10: 1 | H10: 1.66
A11: =IF(NOT(D11=""),INDEX(statAbbr,MATCH(D11,statOfficial,0),1),A10) -> A:T | B11: =INDEX(statID,MATCH(A11,statAbbr,0),1)+INDEX(teamID,MATCH(E11,teamRawName,0)) -> 9505 | E11: Drake | F11: 10 | G11: 1 | H11: 1.66
A12: =IF(NOT(D12=""),INDEX(statAbbr,MATCH(D12,statOfficial,0),1),A11) -> A:T | B12: =INDEX(statID,MATCH(A12,statAbbr,0),1)+INDEX(teamID,MATCH(E12,teamRawName,0)) -> 5505 | E12: Kentucky | F12: 11 | G12: 2 | H12: 1.64
A13: =IF(NOT(D13=""),INDEX(statAbbr,MATCH(D13,statOfficial,0),1),A12) -> A:T | B13: =INDEX(statID,MATCH(A13,statAbbr,0),1)+INDEX(teamID,MATCH(E13,teamRawName,0)) -> 3505 | E13: Tennessee | F13: 12 | G13: 3 | H13: 1.63
A14: =IF(NOT(D14=""),INDEX(statAbbr,MATCH(D14,statOfficial,0),1),A13) -> A:T | B14: =INDEX(statID,MATCH(A14,statAbbr,0),1)+INDEX(teamID,MATCH(E14,teamRawName,0)) -> 3905 | E14: Kansas | F14: 13 | G14: 2 | H14: 1.63
A15: =IF(NOT(D15=""),INDEX(statAbbr,MATCH(D15,statOfficial,0),1),A14) -> A:T | B15: =INDEX(statID,MATCH(A15,statAbbr,0),1)+INDEX(teamID,MATCH(E15,teamRawName,0)) -> 3005 | E15: Purdue | F15: 14 | G15: 3 | H15: 1.63
A16: =IF(NOT(D16=""),INDEX(statAbbr,MATCH(D16,statOfficial,0),1),A15) -> A:T | B16: =INDEX(statID,MATCH(A16,statAbbr,0),1)+INDEX(teamID,MATCH(E16,teamRawName,0)) -> 905 | E16: Michigan St. | F16: 15 | G16: 4 | H16: 1.59
... A71: =IF(NOT(D71=""),INDEX(statAbbr,MATCH(D71,statOfficial,0),1),A70) -> A:T | B71: =INDEX(statID,MATCH(A71,statAbbr,0),1)+INDEX(teamID,MATCH(E71,teamRawName,0)) -> 11905 | E71: Grambling | F71: 342 | G71: 10 | H71: 0.75
A72: =IF(NOT(D72=""),INDEX(statAbbr,MATCH(D72,statOfficial,0),1),A71) -> APG | B72: =INDEX(statID,MATCH(A72,statAbbr,0),1)+INDEX(teamID,MATCH(E72,teamRawName,0)) -> 3906 | D72: Assists Per Game (351 ranked) | E72: Kansas | F72: 1 | G72: 1 | H72: 19 | I72: Kansas | J72: 19
A73: =IF(NOT(D73=""),INDEX(statAbbr,MATCH(D73,statOfficial,0),1),A72) -> APG | B73: =INDEX(statID,MATCH(A73,statAbbr,0),1)+INDEX(teamID,MATCH(E73,teamRawName,0)) -> 2306 | E73: UConn | F73: 2 | G73: 1 | H73: 18.7
A74: =IF(NOT(D74=""),INDEX(statAbbr,MATCH(D74,statOfficial,0),1),A73) -> APG | B74: =INDEX(statID,MATCH(A74,statAbbr,0),1)+INDEX(teamID,MATCH(E74,teamRawName,0)) -> 2706 | E74: BYU | F74: 3 | G74: 2 | H74: 18.5
A75: =IF(NOT(D75=""),INDEX(statAbbr,MATCH(D75,statOfficial,0),1),A74) -> APG | B75: =INDEX(statID,MATCH(A75,statAbbr,0),1)+INDEX(teamID,MATCH(E75,teamRawName,0)) -> 2906 | E75: Arizona | F75: 4 | G75: 1 | H75: 18.5
A76: =IF(NOT(D76=""),INDEX(statAbbr,MATCH(D76,statOfficial,0),1),A75) -> APG | B76: =INDEX(statID,MATCH(A76,statAbbr,0),1)+INDEX(teamID,MATCH(E76,teamRawName,0)) -> 3006 | E76: Purdue | F76: 5 | G76: 1 | H76: 18.5
A77: =IF(NOT(D77=""),INDEX(statAbbr,MATCH(D77,statOfficial,0),1),A76) -> APG | B77: =INDEX(statID,MATCH(A77,statAbbr,0),1)+INDEX(teamID,MATCH(E77,teamRawName,0)) -> 1306 | E77: Colorado St. | F77: 7 | G77: 1 | H77: 18
A78: =IF(NOT(D78=""),INDEX(statAbbr,MATCH(D78,statOfficial,0),1),A77) -> APG | B78: =INDEX(statID,MATCH(A78,statAbbr,0),1)+INDEX(teamID,MATCH(E78,teamRawName,0)) -> 4506 | E78: Auburn | F78: 10 | G78: 1 | H78: 17.8
A79: =IF(NOT(D79=""),INDEX(statAbbr,MATCH(D79,statOfficial,0),1),A78) -> APG | B79: =INDEX(statID,MATCH(A79,statAbbr,0),1)+INDEX(teamID,MATCH(E79,teamRawName,0)) -> 9906 | E79: Samford | F79: 11 | G79: 1 | H79: 17.7
A80: =IF(NOT(D80=""),INDEX(statAbbr,MATCH(D80,statOfficial,0),1),A79) -> APG | B80: =INDEX(statID,MATCH(A80,statAbbr,0),1)+INDEX(teamID,MATCH(E80,teamRawName,0)) -> 5506 | E80: Kentucky | F80: 14 | G80: 2 | H80: 17.5
A81: =IF(NOT(D81=""),INDEX(statAbbr,MATCH(D81,statOfficial,0),1),A80) -> APG | B81: =INDEX(statID,MATCH(A81,statAbbr,0),1)+INDEX(teamID,MATCH(E81,teamRawName,0)) -> 5606 | E81: TCU | F81: 17 | G81: 3 | H81: 16.9
A82: =IF(NOT(D82=""),INDEX(statAbbr,MATCH(D82,statOfficial,0),1),A81) -> APG | B82: =INDEX(statID,MATCH(A82,statAbbr,0),1)+INDEX(teamID,MATCH(E82,teamRawName,0)) -> 3106 | E82: Creighton | F82: 18 | G82: 2 | H82: 16.8
A83: =IF(NOT(D83=""),INDEX(statAbbr,MATCH(D83,statOfficial,0),1),A82) -> APG | B83: =INDEX(statID,MATCH(A83,statAbbr,0),1)+INDEX(teamID,MATCH(E83,teamRawName,0)) -> 4406 | E83: Gonzaga | F83: 19 | G83: 1 | H83: 16.7
A84: =IF(NOT(D84=""),INDEX(statAbbr,MATCH(D84,statOfficial,0),1),A83) -> APG | B84: =INDEX(statID,MATCH(A84,statAbbr,0),1)+INDEX(teamID,MATCH(E84,teamRawName,0)) -> 3506 | E84: Tennessee | F84: 20 | G84: 3 | H84: 16.7
... A139: =IF(NOT(D139=""),INDEX(statAbbr,MATCH(D139,statOfficial,0),1),A138) -> APG | B139: =INDEX(statID,MATCH(A139,statAbbr,0),1)+INDEX(teamID,MATCH(E139,teamRawName,0)) -> 11906 | E139: Grambling | F139: 346 | G139: 11 | H139: 9.8
A140: =IF(NOT(D140=""),INDEX(statAbbr,MATCH(D140,statOfficial,0),1),A139) -> Bench | B140: =INDEX(statID,MATCH(A140,statAbbr,0),1)+INDEX(teamID,MATCH(E140,teamRawName,0)) -> 4507 | D140: Bench Points per game (351 ranked) | E140: Auburn | F140: 4 | G140: 1 | H140: 33.71 | I140: Cornell | J140: 36.03
A141: =IF(NOT(D141=""),INDEX(statAbbr,MATCH(D141,statOfficial,0),1),A140) -> Bench | B141: =INDEX(statID,MATCH(A141,statAbbr,0),1)+INDEX(teamID,MATCH(E141,teamRawName,0)) -> 2707 | E141: BYU | F141: 5 | G141: 1 | H141: 33.5
A142: =IF(NOT(D142=""),INDEX(statAbbr,MATCH(D142,statOfficial,0),1),A141) -> Bench | B142: =INDEX(statID,MATCH(A142,statAbbr,0),1)+INDEX(teamID,MATCH(E142,teamRawName,0)) -> 9907 | E142: Samford | F142: 6 | G142: 1 | H142: 33.29
A143: =IF(NOT(D143=""),INDEX(statAbbr,MATCH(D143,statOfficial,0),1),A142) -> Bench | B143: =INDEX(statID,MATCH(A143,statAbbr,0),1)+INDEX(teamID,MATCH(E143,teamRawName,0)) -> 5507 | E143: Kentucky | F143: 7 | G143: 2 | H143: 32.61
A144: =IF(NOT(D144=""),INDEX(statAbbr,MATCH(D144,statOfficial,0),1),A143) -> Bench | B144: =INDEX(statID,MATCH(A144,statAbbr,0),1)+INDEX(teamID,MATCH(E144,teamRawName,0)) -> 11507 | E144: Col. of Charleston | F144: 11 | G144: 1 | H144: 30.06
A145: =IF(NOT(D145=""),INDEX(statAbbr,MATCH(D145,statOfficial,0),1),A144) -> Bench | B145: =INDEX(statID,MATCH(A145,statAbbr,0),1)+INDEX(teamID,MATCH(E145,teamRawName,0)) -> 12107 | E145: Western Ky. | F145: 18 | G145: 2 | H145: 28.79
A146: =IF(NOT(D146=""),INDEX(statAbbr,MATCH(D146,statOfficial,0),1),A145) -> Bench | B146: =INDEX(statID,MATCH(A146,statAbbr,0),1)+INDEX(teamID,MATCH(E146,teamRawName,0)) -> 5607 | E146: TCU | F146: 28 | G146: 2 | H146: 26.94
A147: =IF(NOT(D147=""),INDEX(statAbbr,MATCH(D147,statOfficial,0),1),A146) -> Bench | B147: =INDEX(statID,MATCH(A147,statAbbr,0),1)+INDEX(teamID,MATCH(E147,teamRawName,0)) -> 11407 | E147: Longwood | F147: 29 | G147: 1 | H147: 26.91
A148: =IF(NOT(D148=""),INDEX(statAbbr,MATCH(D148,statOfficial,0),1),A147) -> Bench | B148: =INDEX(statID,MATCH(A148,statAbbr,0),1)+INDEX(teamID,MATCH(E148,teamRawName,0)) -> 207 | E148: McNeese | F148: 38 | G148: 3 | H148: 25.65
A149: =IF(NOT(D149=""),INDEX(statAbbr,MATCH(D149,statOfficial,0),1),A148) -> Bench | B149: =INDEX(statID,MATCH(A149,statAbbr,0),1)+INDEX(teamID,MATCH(E149,teamRawName,0)) -> 1607 | E149: Mississippi St. | F149: 40 | G149: 6 | H149: 25.57
...

Sheet mapping
A1: BPI+ Value | B1: Stats Map | C1: Count Check | D1: ID | E1: INI | H1: BPI+ Name | I1: Stats Category | J1: Stat ID
A2: Miami | B2: Miami (FL) | C2: =COUNTIF(rawTeamCol,B2)+COUNTIF(rawTeamCol2,B2) -> 28 | D2: 100 | E2: MIA | H2: 3PD% | I2: Three Point Percentage Defense (351 ranked) | J2: 1
A3: McNeese | B3: McNeese | C3: =COUNTIF(rawTeamCol,B3)+COUNTIF(rawTeamCol2,B3) -> 28 | D3: 200 | E3: MCN | H3: 3PPG | I3: Three Pointers Per Game (351 ranked) | J3: 2
A4: Ole Miss | B4: Ole Miss | C4: =COUNTIF(rawTeamCol,B4)+COUNTIF(rawTeamCol2,B4) -> 0 | D4: 300 | E4: MISS | H4: 3PT% | I4: Three Point Percentage (351 ranked) | J4: 3
A5: Fort Wayne | B5: Purdue Fort Wayne | C5: =COUNTIF(rawTeamCol,B5)+COUNTIF(rawTeamCol2,B5) -> 0 | D5: 400 | E5: PFW | H5: 3PTA | I5: Three Point Attempts Per Game (351 ranked) | J5: 4
A6: Florida State | B6: Florida St. | C6: =COUNTIF(rawTeamCol,B6)+COUNTIF(rawTeamCol2,B6) -> 0 | D6: 500 | E6: FSU | H6: A:T | I6: Assist/Turnover Ratio (351 ranked) | J6: 5
A7: Iowa State | B7: Iowa St. | C7: =COUNTIF(rawTeamCol,B7)+COUNTIF(rawTeamCol2,B7) -> 56 | D7: 600 | E7: ISU | H7: APG | I7: Assists Per Game (351 ranked) | J7: 6
A8: Kansas State | B8: Kansas St. | C8: =COUNTIF(rawTeamCol,B8)+COUNTIF(rawTeamCol2,B8) -> 28 | D8: 700 | E8: KSU | H8: Bench | I8: Bench Points per game (350 ranked) | J8: 7
A9: Weber State | B9: Weber St. | C9: =COUNTIF(rawTeamCol,B9)+COUNTIF(rawTeamCol2,B9) -> 0 | D9: 800 | E9: WEB | H9: BPG | I9: Blocks Per Game (351 ranked) | J9: 8
A10: Michigan State | B10: Michigan St. | C10: =COUNTIF(rawTeamCol,B10)+COUNTIF(rawTeamCol2,B10) -> 56 | D10: 900 | E10: MSU | H10: DFG% | I10: Field Goal Percentage Defense (351 ranked) | J10: 9
A11: Ohio State | B11: Ohio St. | C11: =COUNTIF(rawTeamCol,B11)+COUNTIF(rawTeamCol2,B11) -> 0 | D11: 1000 | E11: OSU | H11: DRPG | I11: Rebounds (Defensive) Per Game (351 ranked) | J11: 10
A12: Indiana State | B12: Indiana St. | C12: =COUNTIF(rawTeamCol,B12)+COUNTIF(rawTeamCol2,B12) -> 0 | D12: 1100 | E12: INST | H12: EFG% | I12: Effective FG pct (351 ranked) | J12: 11
A13: San Diego State | B13: San Diego St. | C13: =COUNTIF(rawTeamCol,B13)+COUNTIF(rawTeamCol2,B13) -> 56 | D13: 1200 | E13: SDSU | H13: FB | I13: Fastbreak Points (351 ranked) | J13: 12
... A86: Merrimack | B86: Merrimack | C86: =COUNTIF(rawTeamCol,B86)+COUNTIF(rawTeamCol2,B86) -> 0 | D86: 8500 | E86: MRMK | H86: Bench | I86: Bench Points per game (355 ranked) | J86: 7
A87: Iona | B87: Iona | C87: =COUNTIF(rawTeamCol,B87)+COUNTIF(rawTeamCol2,B87) -> 28 | D87: 8600 | E87: IONA
A88: Stanford | B88: Stanford | C88: =COUNTIF(rawTeamCol,B88)+COUNTIF(rawTeamCol2,B88) -> 0 | D88: 8700 | E88: STAN
A89: Howard | B89: Howard | C89: =COUNTIF(rawTeamCol,B89)+COUNTIF(rawTeamCol2,B89) -> 56 | D89: 8800 | E89: HOW
A90: Winthrop | B90: Winthrop | C90: =COUNTIF(rawTeamCol,B90)+COUNTIF(rawTeamCol2,B90) -> 0 | D90: 8900 | E90: WIN
A91: UCLA | B91: UCLA | C91: =COUNTIF(rawTeamCol,B91)+COUNTIF(rawTeamCol2,B91) -> 28 | D91: 9000 | E91: UCLA
A92: South Carolina | B92: South Carolina | C92: =COUNTIF(rawTeamCol,B92)+COUNTIF(rawTeamCol2,B92) -> 28 | D92: 9100 | E92: SC
A93: UCF | B93: UCF | C93: =COUNTIF(rawTeamCol,B93)+COUNTIF(rawTeamCol2,B93) -> 0 | D93: 9200 | E93: UCF
A94: St. John's | B94: St. John's (NY) | C94: =COUNTIF(rawTeamCol,B94)+COUNTIF(rawTeamCol2,B94) -> 0 | D94: 9300 | E94: SJU
A95: Indiana | B95: Indiana | C95: =COUNTIF(rawTeamCol,B95)+COUNTIF(rawTeamCol2,B95) -> 28 | D95: 9400 | E95: IU
A96: Drake | B96: Drake | C96: =COUNTIF(rawTeamCol,B96)+COUNTIF(rawTeamCol2,B96) -> 56 | D96: 9500 | E96: DRKE
A97: San Francisco | B97: San Francisco | C97: =COUNTIF(rawTeamCol,B97)+COUNTIF(rawTeamCol2,B97) -> 0 | D97: 9600 | E97: SF
A98: Drexel | B98: Drexel | C98: =COUNTIF(rawTeamCol,B98)+COUNTIF(rawTeamCol2,B98) -> 0 | D98: 9700 | E98: DREX
... A110: Oakland | B110: Oakland | C110: =COUNTIF(rawTeamCol,B110)+COUNTIF(rawTeamCol2,B110) -> 28 | D110: 10900 | E110: OAK
A111: Quinnipiac | B111: Quinnipiac | C111: =COUNTIF(rawTeamCol,B111)+COUNTIF(rawTeamCol2,B111) -> 0 | D111: =D110+100 -> 11000 | E111: QUIN
A112: Maryland | B112: Maryland | C112: =COUNTIF(rawTeamCol,B112)+COUNTIF(rawTeamCol2,B112) -> 28 | D112: =D111+100 -> 11100 | E112: MD
A113: USF | B113: South Fla. | C113: =COUNTIF(rawTeamCol,B113)+COUNTIF(rawTeamCol2,B113) -> 0 | D113: =D112+100 -> 11200 | E113: USF
A114: Stetson | B114: Stetson | C114: =COUNTIF(rawTeamCol,B114)+COUNTIF(rawTeamCol2,B114) -> 28 | D114: =D113+100 -> 11300 | E114: STET
A115: Longwood | B115: Longwood | C115: =COUNTIF(rawTeamCol,B115)+COUNTIF(rawTeamCol2,B115) -> 28 | D115: =D114+100 -> 11400 | E115: LONG
A116: Charleston | B116: Col. of Charleston | C116: =COUNTIF(rawTeamCol,B116)+COUNTIF(rawTeamCol2,B116) -> 56 | D116: =D115+100 -> 11500 | E116: COFC
A117: Wagner | B117: Wagner | C117: =COUNTIF(rawTeamCol,B117)+COUNTIF(rawTeamCol2,B117) -> 28 | D117: =D116+100 -> 11600 | E117: WAG
A118: Montana | B118: Montana | C118: =COUNTIF(rawTeamCol,B118)+COUNTIF(rawTeamCol2,B118) -> 0 | D118: =D117+100 -> 11700 | E118: MONT
A119: Texas Southern | B119: Texas Southern | C119: =COUNTIF(rawTeamCol,B119)+COUNTIF(rawTeamCol2,B119) -> 28 | D119: =D118+100 -> 11800 | E119: TXSO
A120: Grambling | B120: Grambling | C120: =COUNTIF(rawTeamCol,B120)+COUNTIF(rawTeamCol2,B120) -> 28 | D120: =D119+100 -> 11900 | E120: GRAM
A121: Montana State | B121: Montana St. | C121: =COUNTIF(rawTeamCol,B121)+COUNTIF(rawTeamCol2,B121) -> 56 | D121: =D120+100 -> 12000 | E121: MTST
A122: Western Kentucky | B122: Western Ky. | C122: =COUNTIF(rawTeamCol,B122)+COUNTIF(rawTeamCol2,B122) -> 28 | D122: =D121+100 -> 12100 | E122: WKU
... A192: Furman | B192: Furman | C192: =COUNTIF(rawTeamCol,B192)+COUNTIF(rawTeamCol2,B192) -> 28 | D192: =D191+100 -> 19100 | E192: FUR

Sheet Structured 2023
A1: Team | B1: Seed | C1: OPP | D1: GAME ID | E1: 3PD% | F1: 3PPG | G1: 3PT% | H1: 3PTA | I1: A:T | J1: APG | K1: Bench | L1: BPG | M1: DFG% | N1: DRPG | O1: EFG% | P1: FB | Q1: FG% | R1: FPG | S1: FT% | T1: FTA | U1: FTPG | V1: OPPG | W1: ORPG | X1: PPG | Y1: RM | Z1: RPG | AA1: SM | AB1: SPG | AC1: TM | AD1: TOF | AE1: TPG | AF1: POSS | AG1: TARGET POSS | AH1: =CONCATENATE("T1_",'Overall 2023 Reference'!G1) -> T1_3PD% | AI1: =CONCATENATE("T1_",'Overall 2023 Reference'!H1) -> T1_3PPG | AJ1: =CONCATENATE("T1_",'Overall 2023 Reference'!I1) -> T1_3PT% | AK1: =CONCATENATE("T1_",'Overall 2023 Reference'!J1) -> T1_3PTA | AL1: =CONCATENATE("T1_",'Overall 2023 Reference'!K1) -> T1_A:T | AM1: =CONCATENATE("T1_",'Overall 2023 Reference'!L1) -> T1_APG | AN1: =CONCATENATE("T1_",'Overall 2023 Reference'!M1) -> T1_Bench | AO1: =CONCATENATE("T1_",'Overall 2023 Reference'!N1) -> T1_BPG | ... BK1: =CONCATENATE("T1_",'Overall 2023 Reference'!AJ1) -> T1_FGA | BL1: =CONCATENATE("T2_",'Overall 2023 Reference'!G1) -> T2_3PD% | BM1: =CONCATENATE("T2_",'Overall 2023 Reference'!H1) -> T2_3PPG | BN1: =CONCATENATE("T2_",'Overall 2023 Reference'!I1) -> T2_3PT% | BO1: =CONCATENATE("T2_",'Overall 2023 Reference'!J1) -> T2_3PTA | BP1: =CONCATENATE("T2_",'Overall 2023 Reference'!K1) -> T2_A:T | BQ1: =CONCATENATE("T2_",'Overall 2023 Reference'!L1) -> T2_APG | BR1: =CONCATENATE("T2_",'Overall 2023 Reference'!M1) -> T2_Bench | BS1: =CONCATENATE("T2_",'Overall 2023 Reference'!N1) -> T2_BPG | ... CO1: =CONCATENATE("T2_",'Overall 2023 Reference'!AJ1) -> T2_FGA
A2: SEMO | B2: 16 | C2: AMCC | D2: 1 | E2: =G3 -> 22.222222 | F2: 8 | G2: =F2/H2*100 -> 30.769231 | H2: 26 | I2: =J2/AE2 -> 1.4166667 | J2: 17 | K2: 16 | L2: 2 | M2: =Q3 -> 38.6 | N2: 24 | O2: =((X2-F2*3-U2)/2+F2*1.5)/(((X2-F2*3-U2)/2+F2)/(G2/100)) -> 0.35327635 | P2: 4 | Q2: 47.4 | R2: 31 | S2: =U2/T2*100 -> 45 | T2: 20 | U2: 9 | V2: =X3 -> 75 | W2: 6 | X2: 71 | Y2: =Z2-Z3 -> -15 | Z2: =W2+N2 -> 30 | AA2: =X2-V2 -> -4 | AB2: 11 | AC2: =AD2-AE2 -> 2 | AD2: =AE3 -> 14 | AE2: 12 | AF2: =(ROUND(((X2-U2-3*F2)/2),0)+F2)/Q2*100-W2+AE2+T2*0.475 -> 72.462025 | AG2: =AVERAGE(AF2,AF3) -> 72.540922 | AH2: =INDEX(ovrTable2,MATCH(INDEX(teamCol2,ROW()),ovrTeamCol2,0),MATCH(MID(INDEX(headerRow2,1,COLUMN()),4,LEN(INDEX(headerRow2,1,COLUMN()))),ovrHeaderRow2,0)) -> 34 | AI2: =INDEX(ovrTable2,MATCH(INDEX(teamCol2,ROW()),ovrTeamCol2,0),MATCH(MID(INDEX(headerRow2,1,COLUMN()),4,LEN(INDEX(headerRow2,1,COLUMN()))),ovrHeaderRow2,0)) -> 8.2 | AJ2: =INDEX(ovrTable2,MATCH(INDEX(teamCol2,ROW()),ovrTeamCol2,0),MATCH(MID(INDEX(headerRow2,1,COLUMN()),4,LEN(INDEX(headerRow2,1,COLUMN()))),ovrHeaderRow2,0)) -> 33.3 | AK2: =INDEX(ovrTable2,MATCH(INDEX(teamCol2,ROW()),ovrTeamCol2,0),MATCH(MID(INDEX(headerRow2,1,COLUMN()),4,LEN(INDEX(headerRow2,1,COLUMN()))),ovrHeaderRow2,0)) -> 24.2 | AL2: =INDEX(ovrTable2,MATCH(INDEX(teamCol2,ROW()),ovrTeamCol2,0),MATCH(MID(INDEX(headerRow2,1,COLUMN()),4,LEN(INDEX(headerRow2,1,COLUMN()))),ovrHeaderRow2,0)) -> 1.14 | AM2: =INDEX(ovrTable2,MATCH(INDEX(teamCol2,ROW()),ovrTeamCol2,0),MATCH(MID(INDEX(headerRow2,1,COLUMN()),4,LEN(INDEX(headerRow2,1,COLUMN()))),ovrHeaderRow2,0)) -> 14 | AN2: =INDEX(ovrTable2,MATCH(INDEX(teamCol2,ROW()),ovrTeamCol2,0),MATCH(MID(INDEX(headerRow2,1,COLUMN()),4,LEN(INDEX(headerRow2,1,COLUMN()))),ovrHeaderRow2,0)) -> 22.46 | AO2: =INDEX(ovrTable2,MATCH(INDEX(teamCol2,ROW()),ovrTeamCol2,0),MATCH(MID(INDEX(headerRow2,1,COLUMN()),4,LEN(INDEX(headerRow2,1,COLUMN()))),ovrHeaderRow2,0)) -> 3.2 | ... BK2: =INDEX(ovrTable2,MATCH(INDEX(teamCol2,ROW()),ovrTeamCol2,0),MATCH(MID(INDEX(headerRow2,1,COLUMN()),4,LEN(INDEX(headerRow2,1,COLUMN()))),ovrHeaderRow2,0)) -> 61.818182 | BL2: =INDEX(ovrTable2,MATCH(INDEX(oppCol23,ROW()),ovrTeamCol2,0),MATCH(MID(INDEX(headerRow2,1,COLUMN()),4,LEN(INDEX(headerRow2,1,COLUMN()))),ovrHeaderRow2,0)) -> 33.5 | BM2: =INDEX(ovrTable2,MATCH(INDEX(oppCol23,ROW()),ovrTeamCol2,0),MATCH(MID(INDEX(headerRow2,1,COLUMN()),4,LEN(INDEX(headerRow2,1,COLUMN()))),ovrHeaderRow2,0)) -> 8 | BN2: =INDEX(ovrTable2,MATCH(INDEX(oppCol23,ROW()),ovrTeamCol2,0),MATCH(MID(INDEX(headerRow2,1,COLUMN()),4,LEN(INDEX(headerRow2,1,COLUMN()))),ovrHeaderRow2,0)) -> 36.1 | BO2: =INDEX(ovrTable2,MATCH(INDEX(oppCol23,ROW()),ovrTeamCol2,0),MATCH(MID(INDEX(headerRow2,1,COLUMN()),4,LEN(INDEX(headerRow2,1,COLUMN()))),ovrHeaderRow2,0)) -> 22.2 | BP2: =INDEX(ovrTable2,MATCH(INDEX(oppCol23,ROW()),ovrTeamCol2,0),MATCH(MID(INDEX(headerRow2,1,COLUMN()),4,LEN(INDEX(headerRow2,1,COLUMN()))),ovrHeaderRow2,0)) -> 1.32 | BQ2: =INDEX(ovrTable2,MATCH(INDEX(oppCol23,ROW()),ovrTeamCol2,0),MATCH(MID(INDEX(headerRow2,1,COLUMN()),4,LEN(INDEX(headerRow2,1,COLUMN()))),ovrHeaderRow2,0)) -> 15.9 | BR2: =INDEX(ovrTable2,MATCH(INDEX(oppCol23,ROW()),ovrTeamCol2,0),MATCH(MID(INDEX(headerRow2,1,COLUMN()),4,LEN(INDEX(headerRow2,1,COLUMN()))),ovrHeaderRow2,0)) -> 26.94 | BS2: =INDEX(ovrTable2,MATCH(INDEX(oppCol23,ROW()),ovrTeamCol2,0),MATCH(MID(INDEX(headerRow2,1,COLUMN()),4,LEN(INDEX(headerRow2,1,COLUMN()))),ovrHeaderRow2,0)) -> 1.6 | ... CO2: =INDEX(ovrTable2,MATCH(INDEX(oppCol23,ROW()),ovrTeamCol2,0),MATCH(MID(INDEX(headerRow2,1,COLUMN()),4,LEN(INDEX(headerRow2,1,COLUMN()))),ovrHeaderRow2,0)) -> 63.576159
A3: AMCC | B3: 16 | C3: SEMO | D3: 1 | E3: =G2 -> 30.769231 | F3: 4 | G3: =F3/H3*100 -> 22.222222 | H3: 18 | I3: =J3/AE3 -> 0.71428571 | J3: 10 | K3: 13 | L3: 1 | M3: =Q2 -> 47.4 | N3: 30 | O3: =((X3-F3*3-U3)/2+F3*1.5)/(((X3-F3*3-U3)/2+F3)/(G3/100)) -> 0.24242424 | P3: 14 | Q3: 38.6 | R3: 18 | S3: =U3/T3*100 -> 77.142857 | T3: 35 | U3: 27 | V3: =X2 -> 71 | W3: 15 | X3: 75 | Y3: =Z3-Z2 -> 15 | Z3: =W3+N3 -> 45 | AA3: =X3-V3 -> 4 | AB3: 3 | AC3: =AD3-AE3 -> -2 | AD3: =AE2 -> 12 | AE3: 14 | AF3: =(ROUND(((X3-U3-3*F3)/2),0)+F3)/Q3*100-W3+AE3+T3*0.475 -> 72.619819 | AG3: =AVERAGE(AF2,AF3) -> 72.540922 | AH3: =INDEX(ovrTable2,MATCH(INDEX(teamCol2,ROW()),ovrTeamCol2,0),MATCH(MID(INDEX(headerRow2,1,COLUMN()),4,LEN(INDEX(headerRow2,1,COLUMN()))),ovrHeaderRow2,0)) -> 33.5 | AI3: =INDEX(ovrTable2,MATCH(INDEX(teamCol2,ROW()),ovrTeamCol2,0),MATCH(MID(INDEX(headerRow2,1,COLUMN()),4,LEN(INDEX(headerRow2,1,COLUMN()))),ovrHeaderRow2,0)) -> 8 | AJ3: =INDEX(ovrTable2,MATCH(INDEX(teamCol2,ROW()),ovrTeamCol2,0),MATCH(MID(INDEX(headerRow2,1,COLUMN()),4,LEN(INDEX(headerRow2,1,COLUMN()))),ovrHeaderRow2,0)) -> 36.1 | AK3: =INDEX(ovrTable2,MATCH(INDEX(teamCol2,ROW()),ovrTeamCol2,0),MATCH(MID(INDEX(headerRow2,1,COLUMN()),4,LEN(INDEX(headerRow2,1,COLUMN()))),ovrHeaderRow2,0)) -> 22.2 | AL3: =INDEX(ovrTable2,MATCH(INDEX(teamCol2,ROW()),ovrTeamCol2,0),MATCH(MID(INDEX(headerRow2,1,COLUMN()),4,LEN(INDEX(headerRow2,1,COLUMN()))),ovrHeaderRow2,0)) -> 1.32 | AM3: =INDEX(ovrTable2,MATCH(INDEX(teamCol2,ROW()),ovrTeamCol2,0),MATCH(MID(INDEX(headerRow2,1,COLUMN()),4,LEN(INDEX(headerRow2,1,COLUMN()))),ovrHeaderRow2,0)) -> 15.9 | AN3: =INDEX(ovrTable2,MATCH(INDEX(teamCol2,ROW()),ovrTeamCol2,0),MATCH(MID(INDEX(headerRow2,1,COLUMN()),4,LEN(INDEX(headerRow2,1,COLUMN()))),ovrHeaderRow2,0)) -> 26.94 | AO3: =INDEX(ovrTable2,MATCH(INDEX(teamCol2,ROW()),ovrTeamCol2,0),MATCH(MID(INDEX(headerRow2,1,COLUMN()),4,LEN(INDEX(headerRow2,1,COLUMN()))),ovrHeaderRow2,0)) -> 1.6 | ... BK3: =INDEX(ovrTable2,MATCH(INDEX(teamCol2,ROW()),ovrTeamCol2,0),MATCH(MID(INDEX(headerRow2,1,COLUMN()),4,LEN(INDEX(headerRow2,1,COLUMN()))),ovrHeaderRow2,0)) -> 63.576159 | BL3: =INDEX(ovrTable2,MATCH(INDEX(oppCol23,ROW()),ovrTeamCol2,0),MATCH(MID(INDEX(headerRow2,1,COLUMN()),4,LEN(INDEX(headerRow2,1,COLUMN()))),ovrHeaderRow2,0)) -> 34 | BM3: =INDEX(ovrTable2,MATCH(INDEX(oppCol23,ROW()),ovrTeamCol2,0),MATCH(MID(INDEX(headerRow2,1,COLUMN()),4,LEN(INDEX(headerRow2,1,COLUMN()))),ovrHeaderRow2,0)) -> 8.2 | BN3: =INDEX(ovrTable2,MATCH(INDEX(oppCol23,ROW()),ovrTeamCol2,0),MATCH(MID(INDEX(headerRow2,1,COLUMN()),4,LEN(INDEX(headerRow2,1,COLUMN()))),ovrHeaderRow2,0)) -> 33.3 | BO3: =INDEX(ovrTable2,MATCH(INDEX(oppCol23,ROW()),ovrTeamCol2,0),MATCH(MID(INDEX(headerRow2,1,COLUMN()),4,LEN(INDEX(headerRow2,1,COLUMN()))),ovrHeaderRow2,0)) -> 24.2 | BP3: =INDEX(ovrTable2,MATCH(INDEX(oppCol23,ROW()),ovrTeamCol2,0),MATCH(MID(INDEX(headerRow2,1,COLUMN()),4,LEN(INDEX(headerRow2,1,COLUMN()))),ovrHeaderRow2,0)) -> 1.14 | BQ3: =INDEX(ovrTable2,MATCH(INDEX(oppCol23,ROW()),ovrTeamCol2,0),MATCH(MID(INDEX(headerRow2,1,COLUMN()),4,LEN(INDEX(headerRow2,1,COLUMN()))),ovrHeaderRow2,0)) -> 14 | BR3: =INDEX(ovrTable2,MATCH(INDEX(oppCol23,ROW()),ovrTeamCol2,0),MATCH(MID(INDEX(headerRow2,1,COLUMN()),4,LEN(INDEX(headerRow2,1,COLUMN()))),ovrHeaderRow2,0)) -> 22.46 | BS3: =INDEX(ovrTable2,MATCH(INDEX(oppCol23,ROW()),ovrTeamCol2,0),MATCH(MID(INDEX(headerRow2,1,COLUMN()),4,LEN(INDEX(headerRow2,1,COLUMN()))),ovrHeaderRow2,0)) -> 3.2 | ... CO3: =INDEX(ovrTable2,MATCH(INDEX(oppCol23,ROW()),ovrTeamCol2,0),MATCH(MID(INDEX(headerRow2,1,COLUMN()),4,LEN(INDEX(headerRow2,1,COLUMN()))),ovrHeaderRow2,0)) -> 61.818182
A4: MSST | B4: 11 | C4: PITT | D4: 2 | E4: =G5 -> 47.368421 | F4: 6 | G4: =F4/H4*100 -> 26.086957 | H4: 23 | I4: =J4/AE4 -> 1 | J4: 14 | K4: 6 | L4: 4 | M4: =Q5 -> 38.9 | N4: 31 | O4: =((X4-F4*3-U4)/2+F4*1.5)/(((X4-F4*3-U4)/2+F4)/(G4/100)) -> 0.29347826 | P4: 2 | Q4: 38.1 | R4: 18 | S4: =U4/T4*100 -> 71.428571 | T4: 7 | U4: 5 | V4: =X5 -> 60 | W4: 18 | X4: 59 | Y4: =Z4-Z5 -> 21 | Z4: =W4+N4 -> 49 | AA4: =X4-V4 -> -1 | AB4: 1 | AC4: =AD4-AE4 -> -7 | AD4: =AE5 -> 7 | AE4: 14 | AF4: =(ROUND(((X4-U4-3*F4)/2),0)+F4)/Q4*100-W4+AE4+T4*0.475 -> 62.317126 | AG4: =AVERAGE(AF4,AF5) -> 62.213351 | AH4: =INDEX(ovrTable2,MATCH(INDEX(teamCol2,ROW()),ovrTeamCol2,0),MATCH(MID(INDEX(headerRow2,1,COLUMN()),4,LEN(INDEX(headerRow2,1,COLUMN()))),ovrHeaderRow2,0)) -> 31.7 | AI4: =INDEX(ovrTable2,MATCH(INDEX(teamCol2,ROW()),ovrTeamCol2,0),MATCH(MID(INDEX(headerRow2,1,COLUMN()),4,LEN(INDEX(headerRow2,1,COLUMN()))),ovrHeaderRow2,0)) -> 5.7 | AJ4: =INDEX(ovrTable2,MATCH(INDEX(teamCol2,ROW()),ovrTeamCol2,0),MATCH(MID(INDEX(headerRow2,1,COLUMN()),4,LEN(INDEX(headerRow2,1,COLUMN()))),ovrHeaderRow2,0)) -> 29.3 | AK4: =INDEX(ovrTable2,MATCH(INDEX(teamCol2,ROW()),ovrTeamCol2,0),MATCH(MID(INDEX(headerRow2,1,COLUMN()),4,LEN(INDEX(headerRow2,1,COLUMN()))),ovrHeaderRow2,0)) -> 20.2 | AL4: =INDEX(ovrTable2,MATCH(INDEX(teamCol2,ROW()),ovrTeamCol2,0),MATCH(MID(INDEX(headerRow2,1,COLUMN()),4,LEN(INDEX(headerRow2,1,COLUMN()))),ovrHeaderRow2,0)) -> 1.22 | AM4: =INDEX(ovrTable2,MATCH(INDEX(teamCol2,ROW()),ovrTeamCol2,0),MATCH(MID(INDEX(headerRow2,1,COLUMN()),4,LEN(INDEX(headerRow2,1,COLUMN()))),ovrHeaderRow2,0)) -> 14.7 | AN4: =INDEX(ovrTable2,MATCH(INDEX(teamCol2,ROW()),ovrTeamCol2,0),MATCH(MID(INDEX(headerRow2,1,COLUMN()),4,LEN(INDEX(headerRow2,1,COLUMN()))),ovrHeaderRow2,0)) -> 17.76 | AO4: =INDEX(ovrTable2,MATCH(INDEX(teamCol2,ROW()),ovrTeamCol2,0),MATCH(MID(INDEX(headerRow2,1,COLUMN()),4,LEN(INDEX(headerRow2,1,COLUMN()))),ovrHeaderRow2,0)) -> 3.7 | ... BK4: =INDEX(ovrTable2,MATCH(INDEX(teamCol2,ROW()),ovrTeamCol2,0),MATCH(MID(INDEX(headerRow2,1,COLUMN()),4,LEN(INDEX(headerRow2,1,COLUMN()))),ovrHeaderRow2,0)) -> 55.348259 | BL4: =INDEX(ovrTable2,MATCH(INDEX(oppCol23,ROW()),ovrTeamCol2,0),MATCH(MID(INDEX(headerRow2,1,COLUMN()),4,LEN(INDEX(headerRow2,1,COLUMN()))),ovrHeaderRow2,0)) -> 32.3 | BM4: =INDEX(ovrTable2,MATCH(INDEX(oppCol23,ROW()),ovrTeamCol2,0),MATCH(MID(INDEX(headerRow2,1,COLUMN()),4,LEN(INDEX(headerRow2,1,COLUMN()))),ovrHeaderRow2,0)) -> 8.9 | BN4: =INDEX(ovrTable2,MATCH(INDEX(oppCol23,ROW()),ovrTeamCol2,0),MATCH(MID(INDEX(headerRow2,1,COLUMN()),4,LEN(INDEX(headerRow2,1,COLUMN()))),ovrHeaderRow2,0)) -> 35.9 | BO4: =INDEX(ovrTable2,MATCH(INDEX(oppCol23,ROW()),ovrTeamCol2,0),MATCH(MID(INDEX(headerRow2,1,COLUMN()),4,LEN(INDEX(headerRow2,1,COLUMN()))),ovrHeaderRow2,0)) -> 25.1 | BP4: =INDEX(ovrTable2,MATCH(INDEX(oppCol23,ROW()),ovrTeamCol2,0),MATCH(MID(INDEX(headerRow2,1,COLUMN()),4,LEN(INDEX(headerRow2,1,COLUMN()))),ovrHeaderRow2,0)) -> 1.41 | BQ4: =INDEX(ovrTable2,MATCH(INDEX(oppCol23,ROW()),ovrTeamCol2,0),MATCH(MID(INDEX(headerRow2,1,COLUMN()),4,LEN(INDEX(headerRow2,1,COLUMN()))),ovrHeaderRow2,0)) -> 14.6 | BR4: =INDEX(ovrTable2,MATCH(INDEX(oppCol23,ROW()),ovrTeamCol2,0),MATCH(MID(INDEX(headerRow2,1,COLUMN()),4,LEN(INDEX(headerRow2,1,COLUMN()))),ovrHeaderRow2,0)) -> 16.66 | BS4: =INDEX(ovrTable2,MATCH(INDEX(oppCol23,ROW()),ovrTeamCol2,0),MATCH(MID(INDEX(headerRow2,1,COLUMN()),4,LEN(INDEX(headerRow2,1,COLUMN()))),ovrHeaderRow2,0)) -> 4.1 | ... CO4: =INDEX(ovrTable2,MATCH(INDEX(oppCol23,ROW()),ovrTeamCol2,0),MATCH(MID(INDEX(headerRow2,1,COLUMN()),4,LEN(INDEX(headerRow2,1,COLUMN()))),ovrHeaderRow2,0)) -> 58.129176
A5: PITT | B5: 11 | C5: MSST | D5: 2 | E5: =G4 -> 26.086957 | F5: 9 | G5: =F5/H5*100 -> 47.368421 | H5: 19 | I5: =J5/AE5 -> 1.4285714 | J5: 10 | K5: 11 | L5: 4 | M5: =Q4 -> 38.1 | N5: 22 | O5: =((X5-F5*3-U5)/2+F5*1.5)/(((X5-F5*3-U5)/2+F5)/(G5/100)) -> 0.57518797 | P5: 6 | Q5: 38.9 | R5: 12 | S5: =U5/T5*100 -> 60 | T5: 15 | U5: 9 | V5: =X4 -> 59 | W5: 6 | X5: 60 | Y5: =Z5-Z4 -> -21 | Z5: =W5+N5 -> 28 | AA5: =X5-V5 -> 1 | AB5: 7 | AC5: =AD5-AE5 -> 7 | AD5: =AE4 -> 14 | AE5: 7 | AF5: =(ROUND(((X5-U5-3*F5)/2),0)+F5)/Q5*100-W5+AE5+T5*0.475 -> 62.109576 | AG5: =AVERAGE(AF4,AF5) -> 62.213351 | AH5: =INDEX(ovrTable2,MATCH(INDEX(teamCol2,ROW()),ovrTeamCol2,0),MATCH(MID(INDEX(headerRow2,1,COLUMN()),4,LEN(INDEX(headerRow2,1,COLUMN()))),ovrHeaderRow2,0)) -> 32.3 | AI5: =INDEX(ovrTable2,MATCH(INDEX(teamCol2,ROW()),ovrTeamCol2,0),MATCH(MID(INDEX(headerRow2,1,COLUMN()),4,LEN(INDEX(headerRow2,1,COLUMN()))),ovrHeaderRow2,0)) -> 8.9 | AJ5: =INDEX(ovrTable2,MATCH(INDEX(teamCol2,ROW()),ovrTeamCol2,0),MATCH(MID(INDEX(headerRow2,1,COLUMN()),4,LEN(INDEX(headerRow2,1,COLUMN()))),ovrHeaderRow2,0)) -> 35.9 | AK5: =INDEX(ovrTable2,MATCH(INDEX(teamCol2,ROW()),ovrTeamCol2,0),MATCH(MID(INDEX(headerRow2,1,COLUMN()),4,LEN(INDEX(headerRow2,1,COLUMN()))),ovrHeaderRow2,0)) -> 25.1 | AL5: =INDEX(ovrTable2,MATCH(INDEX(teamCol2,ROW()),ovrTeamCol2,0),MATCH(MID(INDEX(headerRow2,1,COLUMN()),4,LEN(INDEX(headerRow2,1,COLUMN()))),ovrHeaderRow2,0)) -> 1.41 | AM5: =INDEX(ovrTable2,MATCH(INDEX(teamCol2,ROW()),ovrTeamCol2,0),MATCH(MID(INDEX(headerRow2,1,COLUMN()),4,LEN(INDEX(headerRow2,1,COLUMN()))),ovrHeaderRow2,0)) -> 14.6 | AN5: =INDEX(ovrTable2,MATCH(INDEX(teamCol2,ROW()),ovrTeamCol2,0),MATCH(MID(INDEX(headerRow2,1,COLUMN()),4,LEN(INDEX(headerRow2,1,COLUMN()))),ovrHeaderRow2,0)) -> 16.66 | AO5: =INDEX(ovrTable2,MATCH(INDEX(teamCol2,ROW()),ovrTeamCol2,0),MATCH(MID(INDEX(headerRow2,1,COLUMN()),4,LEN(INDEX(headerRow2,1,COLUMN()))),ovrHeaderRow2,0)) -> 4.1 | ... BK5: =INDEX(ovrTable2,MATCH(INDEX(teamCol2,ROW()),ovrTeamCol2,0),MATCH(MID(INDEX(headerRow2,1,COLUMN()),4,LEN(INDEX(headerRow2,1,COLUMN()))),ovrHeaderRow2,0)) -> 58.129176 | BL5: =INDEX(ovrTable2,MATCH(INDEX(oppCol23,ROW()),ovrTeamCol2,0),MATCH(MID(INDEX(headerRow2,1,COLUMN()),4,LEN(INDEX(headerRow2,1,COLUMN()))),ovrHeaderRow2,0)) -> 31.7 | BM5: =INDEX(ovrTable2,MATCH(INDEX(oppCol23,ROW()),ovrTeamCol2,0),MATCH(MID(INDEX(headerRow2,1,COLUMN()),4,LEN(INDEX(headerRow2,1,COLUMN()))),ovrHeaderRow2,0)) -> 5.7 | BN5: =INDEX(ovrTable2,MATCH(INDEX(oppCol23,ROW()),ovrTeamCol2,0),MATCH(MID(INDEX(headerRow2,1,COLUMN()),4,LEN(INDEX(headerRow2,1,COLUMN()))),ovrHeaderRow2,0)) -> 29.3 | BO5: =INDEX(ovrTable2,MATCH(INDEX(oppCol23,ROW()),ovrTeamCol2,0),MATCH(MID(INDEX(headerRow2,1,COLUMN()),4,LEN(INDEX(headerRow2,1,COLUMN()))),ovrHeaderRow2,0)) -> 20.2 | BP5: =INDEX(ovrTable2,MATCH(INDEX(oppCol23,ROW()),ovrTeamCol2,0),MATCH(MID(INDEX(headerRow2,1,COLUMN()),4,LEN(INDEX(headerRow2,1,COLUMN()))),ovrHeaderRow2,0)) -> 1.22 | BQ5: =INDEX(ovrTable2,MATCH(INDEX(oppCol23,ROW()),ovrTeamCol2,0),MATCH(MID(INDEX(headerRow2,1,COLUMN()),4,LEN(INDEX(headerRow2,1,COLUMN()))),ovrHeaderRow2,0)) -> 14.7 | BR5: =INDEX(ovrTable2,MATCH(INDEX(oppCol23,ROW()),ovrTeamCol2,0),MATCH(MID(INDEX(headerRow2,1,COLUMN()),4,LEN(INDEX(headerRow2,1,COLUMN()))),ovrHeaderRow2,0)) -> 17.76 | BS5: =INDEX(ovrTable2,MATCH(INDEX(oppCol23,ROW()),ovrTeamCol2,0),MATCH(MID(INDEX(headerRow2,1,COLUMN()),4,LEN(INDEX(headerRow2,1,COLUMN()))),ovrHeaderRow2,0)) -> 3.7 | ... CO5: =INDEX(ovrTable2,MATCH(INDEX(oppCol23,ROW()),ovrTeamCol2,0),MATCH(MID(INDEX(headerRow2,1,COLUMN()),4,LEN(INDEX(headerRow2,1,COLUMN()))),ovrHeaderRow2,0)) -> 55.348259
A6: NEV | B6: 11 | C6: ASU | D6: 3 | E6: =G7 -> 52.380952 | F6: 11 | G6: =F6/H6*100 -> 52.380952 | H6: 21 | I6: =J6/AE6 -> 1.7272727 | J6: 19 | K6: 19 | L6: 0 | M6: =Q7 -> 63.6 | N6: 20 | O6: =((X6-F6*3-U6)/2+F6*1.5)/(((X6-F6*3-U6)/2+F6)/(G6/100)) -> 0.63904762 | P6: 7 | Q6: 48.1 | R6: 18 | S6: =U6/T6*100 -> 85.714286 | T6: 14 | U6: 12 | V6: =X7 -> 98 | W6: 5 | X6: 73 | Y6: =Z6-Z7 -> -3 | Z6: =W6+N6 -> 25 | AA6: =X6-V6 -> -25 | AB6: 3 | AC6: =AD6-AE6 -> -4 | AD6: =AE7 -> 7 | AE6: 11 | AF6: =(ROUND(((X6-U6-3*F6)/2),0)+F6)/Q6*100-W6+AE6+T6*0.475 -> 64.625052 | AG6: =AVERAGE(AF6,AF7) -> 67.028249 | AH6: =INDEX(ovrTable2,MATCH(INDEX(teamCol2,ROW()),ovrTeamCol2,0),MATCH(MID(INDEX(headerRow2,1,COLUMN()),4,LEN(INDEX(headerRow2,1,COLUMN()))),ovrHeaderRow2,0)) -> 32.5 | AI6: =INDEX(ovrTable2,MATCH(INDEX(teamCol2,ROW()),ovrTeamCol2,0),MATCH(MID(INDEX(headerRow2,1,COLUMN()),4,LEN(INDEX(headerRow2,1,COLUMN()))),ovrHeaderRow2,0)) -> 7.3 | AJ6: =INDEX(ovrTable2,MATCH(INDEX(teamCol2,ROW()),ovrTeamCol2,0),MATCH(MID(INDEX(headerRow2,1,COLUMN()),4,LEN(INDEX(headerRow2,1,COLUMN()))),ovrHeaderRow2,0)) -> 35.5 | AK6: =INDEX(ovrTable2,MATCH(INDEX(teamCol2,ROW()),ovrTeamCol2,0),MATCH(MID(INDEX(headerRow2,1,COLUMN()),4,LEN(INDEX(headerRow2,1,COLUMN()))),ovrHeaderRow2,0)) -> 21.6 | AL6: =INDEX(ovrTable2,MATCH(INDEX(teamCol2,ROW()),ovrTeamCol2,0),MATCH(MID(INDEX(headerRow2,1,COLUMN()),4,LEN(INDEX(headerRow2,1,COLUMN()))),ovrHeaderRow2,0)) -> 1.58 | AM6: =INDEX(ovrTable2,MATCH(INDEX(teamCol2,ROW()),ovrTeamCol2,0),MATCH(MID(INDEX(headerRow2,1,COLUMN()),4,LEN(INDEX(headerRow2,1,COLUMN()))),ovrHeaderRow2,0)) -> 14.9 | AN6: =INDEX(ovrTable2,MATCH(INDEX(teamCol2,ROW()),ovrTeamCol2,0),MATCH(MID(INDEX(headerRow2,1,COLUMN()),4,LEN(INDEX(headerRow2,1,COLUMN()))),ovrHeaderRow2,0)) -> 15.03 | AO6: =INDEX(ovrTable2,MATCH(INDEX(teamCol2,ROW()),ovrTeamCol2,0),MATCH(MID(INDEX(headerRow2,1,COLUMN()),4,LEN(INDEX(headerRow2,1,COLUMN()))),ovrHeaderRow2,0)) -> 3.1 | ... BK6: =INDEX(ovrTable2,MATCH(INDEX(teamCol2,ROW()),ovrTeamCol2,0),MATCH(MID(INDEX(headerRow2,1,COLUMN()),4,LEN(INDEX(headerRow2,1,COLUMN()))),ovrHeaderRow2,0)) -> 55.233853 | BL6: =INDEX(ovrTable2,MATCH(INDEX(oppCol23,ROW()),ovrTeamCol2,0),MATCH(MID(INDEX(headerRow2,1,COLUMN()),4,LEN(INDEX(headerRow2,1,COLUMN()))),ovrHeaderRow2,0)) -> 33.9 | BM6: =INDEX(ovrTable2,MATCH(INDEX(oppCol23,ROW()),ovrTeamCol2,0),MATCH(MID(INDEX(headerRow2,1,COLUMN()),4,LEN(INDEX(headerRow2,1,COLUMN()))),ovrHeaderRow2,0)) -> 7.8 | BN6: =INDEX(ovrTable2,MATCH(INDEX(oppCol23,ROW()),ovrTeamCol2,0),MATCH(MID(INDEX(headerRow2,1,COLUMN()),4,LEN(INDEX(headerRow2,1,COLUMN()))),ovrHeaderRow2,0)) -> 32.8 | BO6: =INDEX(ovrTable2,MATCH(INDEX(oppCol23,ROW()),ovrTeamCol2,0),MATCH(MID(INDEX(headerRow2,1,COLUMN()),4,LEN(INDEX(headerRow2,1,COLUMN()))),ovrHeaderRow2,0)) -> 23.7 | BP6: =INDEX(ovrTable2,MATCH(INDEX(oppCol23,ROW()),ovrTeamCol2,0),MATCH(MID(INDEX(headerRow2,1,COLUMN()),4,LEN(INDEX(headerRow2,1,COLUMN()))),ovrHeaderRow2,0)) -> 1.34 | BQ6: =INDEX(ovrTable2,MATCH(INDEX(oppCol23,ROW()),ovrTeamCol2,0),MATCH(MID(INDEX(headerRow2,1,COLUMN()),4,LEN(INDEX(headerRow2,1,COLUMN()))),ovrHeaderRow2,0)) -> 14.8 | BR6: =INDEX(ovrTable2,MATCH(INDEX(oppCol23,ROW()),ovrTeamCol2,0),MATCH(MID(INDEX(headerRow2,1,COLUMN()),4,LEN(INDEX(headerRow2,1,COLUMN()))),ovrHeaderRow2,0)) -> 17.42 | BS6: =INDEX(ovrTable2,MATCH(INDEX(oppCol23,ROW()),ovrTeamCol2,0),MATCH(MID(INDEX(headerRow2,1,COLUMN()),4,LEN(INDEX(headerRow2,1,COLUMN()))),ovrHeaderRow2,0)) -> 4.5 | ... CO6: =INDEX(ovrTable2,MATCH(INDEX(oppCol23,ROW()),ovrTeamCol2,0),MATCH(MID(INDEX(headerRow2,1,COLUMN()),4,LEN(INDEX(headerRow2,1,COLUMN()))),ovrHeaderRow2,0)) -> 66.035354
