Workbook
Name averages: 'BPI+'!$FK$4:$GP$4
Name bchk1: 'Map of Bracket (for Pred Tools)'!$D$1:$E$16
Name bchk2: 'Map of Bracket (for Pred Tools)'!$D$19:$E$34
Name bchk3: 'Map of Bracket (for Pred Tools)'!$D$36:$E$51
Name bchk4: 'Map of Bracket (for Pred Tools)'!$D$54:$E$69
Name bpiHeaders: 'BPI+'!$1:$1
Name bpiImportCol: 'BPI Import'!$A:$A
Name bpiPlusHeader: 'BPI+'!$A$1:$GP$1
Name bpiPlusTable: 'BPI+'!$A$1:$GQ$279
Name bpiTeams: 'BPI+'!$C:$C
Name bracketLeft: Bracket!$D$2:$M$33
Name bracketRight: Bracket!$P$2:$X$33
Name calculatedResVal: 'Res Value'!$BT:$BT
Name conf1: Seeding!$C:$C
Name conf2: Seeding!$G:$G
Name espnMap: mapping!$J:$J
Name espnMap2: mapping!$K:$K
Name FGA_COEFFS: Formulas!$A$3:$H$3
Name FTA_COEFFS: Formulas!$A$31:$F$31
Name FTPCT_COEFFS: Formulas!$A$38:$D$38
Name fullSDevTable: 'BPI+'!$EC:$FF
Name importBPICol: 'BPI Import'!$B:$B
Name importBPIRkCol: 'BPI Import'!$C:$C
Name INIcol: mapping!$I:$I
Name kpDef: 'KenPom import'!$I:$I
Name kpOff: 'KenPom import'!$G:$G
Name kpTeam: 'KenPom import'!$B:$B
Name kpVal: mapping!$D:$D
Name mascotCol: 'BPI+'!$D:$D
Name perc3pt: 'BPI+'!$FH:$FH
Name qlTable: 'BPI+'!$BL:$BX
Name quad1: 'Map of Bracket (for Pred Tools)'!$C$1:$C$16
Name quadcheck: 'Map of Bracket (for Pred Tools)'!$P$1
Name quadrant1: 'Map of Bracket (for Pred Tools)'!$C$1:$E$16
Name quadrant2: 'Map of Bracket (for Pred Tools)'!$C$19:$E$34
Name quadrant3: 'Map of Bracket (for Pred Tools)'!$C$36:$E$51
Name quadrant4: 'Map of Bracket (for Pred Tools)'!$C$54:$E$69
Name qwqlINIcol: 'Res Value'!$B:$B
Name rank1: Seeding!$A:$A
Name rank2: Seeding!$E:$E
Name resValueTeamCol: 'Res Value'!$A:$A
Name RKTEAM: 'BPI+'!$A:$C
Name rlTable: 'BPI+'!$AK:$AV
Name rowOffset: mapping!$N$2
Name sdevHeader: 'BPI+'!$EC$1:$FF$1
Name sdevTable: 'BPI+'!$EC$1:$FF$53
Name sorCol: 'BPI+'!$J:$J
Name sorRkCol: 'SOR Import'!$B:$B
Name sorRowOffset: mapping!$N$5
Name sorTeamCol: 'SOR Import'!$A:$A
Name statsCategories: 'BPI+'!$CX$1:$DX$1
Name statsNames: mapping!$P:$Q
Name STATSTABLE: 'BPI+'!$CX:$EB
Name statsTable2: 'BPI+'!$CX$1:$FH$53
Name statsTable2header: 'BPI+'!$CX$1:$FH$1
Name statsTitles: '1v1 (Prediction Tool)'!$A$6
Name statTitles: 'BPI+'!$CX$1:$EB$1
Name team1: Seeding!$B:$B
Name team2: Seeding!$F:$F
Name teamA: Bracket!$AE$2

Sheet Stats import
D1: Statistic | E1: Team | F1: National | G1: Conference | H1: Value | I1: National Leader | J1: Value
A2: =IF(NOT(D2=""),INDEX(statsNames,MATCH(D2,mapping!Q:Q,0),1),A1) -> 0 | B2: =INDEX(mapping!R:R,MATCH(A2,mapping!P:P,0),1)+INDEX(mapping!H:H,MATCH(E2,mapping!F:F,0)) -> #N/A | F2: Rank | G2: Rank
A3: =IF(NOT(D3=""),INDEX(statsNames,MATCH(D3,mapping!Q:Q,0),1),A2) -> A:T | B3: =INDEX(mapping!R:R,MATCH(A3,mapping!P:P,0),1)+INDEX(mapping!H:H,MATCH(E3,mapping!F:F,0)) -> 3005 | D3: Assist/Turnover Ratio (361 ranked) | E3: Purdue | F3: 1 | G3: 1 | H3: 2.19 | I3: Purdue | J3: 2.19
A4: =IF(NOT(D4=""),INDEX(statsNames,MATCH(D4,mapping!Q:Q,0),1),A3) -> A:T | B4: =INDEX(mapping!R:R,MATCH(A4,mapping!P:P,0),1)+INDEX(mapping!H:H,MATCH(E4,mapping!F:F,0)) -> 5105 | E4: Liberty | F4: 3 | G4: 1 | H4: 1.95
A5: =IF(NOT(D5=""),INDEX(statsNames,MATCH(D5,mapping!Q:Q,0),1),A4) -> A:T | B5: =INDEX(mapping!R:R,MATCH(A5,mapping!P:P,0),1)+INDEX(mapping!H:H,MATCH(E5,mapping!F:F,0)) -> 4405 | E5: Gonzaga | F5: 4 | G5: 1 | H5: 1.9
A6: =IF(NOT(D6=""),INDEX(statsNames,MATCH(D6,mapping!Q:Q,0),1),A5) -> A:T | B6: =INDEX(mapping!R:R,MATCH(A6,mapping!P:P,0),1)+INDEX(mapping!H:H,MATCH(E6,mapping!F:F,0)) -> 8105 | E6: Arkansas | F6: 5 | G6: 1 | H6: 1.88
A7: =IF(NOT(D7=""),INDEX(statsNames,MATCH(D7,mapping!Q:Q,0),1),A6) -> A:T | B7: =INDEX(mapping!R:R,MATCH(A7,mapping!P:P,0),1)+INDEX(mapping!H:H,MATCH(E7,mapping!F:F,0)) -> 7305 | E7: Nebraska | F7: 6 | G7: 3 | H7: 1.84
A8: =IF(NOT(D8=""),INDEX(statsNames,MATCH(D8,mapping!Q:Q,0),1),A7) -> A:T | B8: =INDEX(mapping!R:R,MATCH(A8,mapping!P:P,0),1)+INDEX(mapping!H:H,MATCH(E8,mapping!F:F,0)) -> 9005 | E8: UCLA | F8: 7 | G8: 4 | H8: 1.84
A9: =IF(NOT(D9=""),INDEX(statsNames,MATCH(D9,mapping!Q:Q,0),1),A8) -> A:T | B9: =INDEX(mapping!R:R,MATCH(A9,mapping!P:P,0),1)+INDEX(mapping!H:H,MATCH(E9,mapping!F:F,0)) -> 4205 | E9: Wisconsin | F9: 10 | G9: 5 | H9: 1.79
A10: =IF(NOT(D10=""),INDEX(statsNames,MATCH(D10,mapping!Q:Q,0),1),A9) -> A:T | B10: =INDEX(mapping!R:R,MATCH(A10,mapping!P:P,0),1)+INDEX(mapping!H:H,MATCH(E10,mapping!F:F,0)) -> 10605 | E10: High Point | F10: 12 | G10: 1 | H10: 1.74
A11: =IF(NOT(D11=""),INDEX(statsNames,MATCH(D11,mapping!Q:Q,0),1),A10) -> A:T | B11: =INDEX(mapping!R:R,MATCH(A11,mapping!P:P,0),1)+INDEX(mapping!H:H,MATCH(E11,mapping!F:F,0)) -> 12505 | E11: Yale | F11: 13 | G11: 2 | H11: 1.73
A12: =IF(NOT(D12=""),INDEX(statsNames,MATCH(D12,mapping!Q:Q,0),1),A11) -> A:T | B12: =INDEX(mapping!R:R,MATCH(A12,mapping!P:P,0),1)+INDEX(mapping!H:H,MATCH(E12,mapping!F:F,0)) -> 2805 | E12: Houston | F12: 14 | G12: 1 | H12: 1.73
A13: =IF(NOT(D13=""),INDEX(statsNames,MATCH(D13,mapping!Q:Q,0),1),A12) -> A:T | B13: =INDEX(mapping!R:R,MATCH(A13,mapping!P:P,0),1)+INDEX(mapping!H:H,MATCH(E13,mapping!F:F,0)) -> 14405 | E13: Vanderbilt | F13: 15 | G13: 2 | H13: 1.72
A14: =IF(NOT(D14=""),INDEX(statsNames,MATCH(D14,mapping!Q:Q,0),1),A13) -> A:T | B14: =INDEX(mapping!R:R,MATCH(A14,mapping!P:P,0),1)+INDEX(mapping!H:H,MATCH(E14,mapping!F:F,0)) -> 1905 | E14: NC State | F14: 16 | G14: 1 | H14: 1.69
A15: =IF(NOT(D15=""),INDEX(statsNames,MATCH(D15,mapping!Q:Q,0),1),A14) -> A:T | B15: =INDEX(mapping!R:R,MATCH(A15,mapping!P:P,0),1)+INDEX(mapping!H:H,MATCH(E15,mapping!F:F,0)) -> 8205 | E15: Akron | F15: 18 | G15: 1 | H15: 1.69
... A89: =IF(NOT(D89=""),INDEX(statsNames,MATCH(D89,mapping!Q:Q,0),1),A88) -> A:T | B89: =INDEX(mapping!R:R,MATCH(A89,mapping!P:P,0),1)+INDEX(mapping!H:H,MATCH(E89,mapping!F:F,0)) -> 18205 | E89: Bethune-Cookman | F89: 309 | G89: 5 | H89: 0.99
A90: =IF(NOT(D90=""),INDEX(statsNames,MATCH(D90,mapping!Q:Q,0),1),A89) -> APG | B90: =INDEX(mapping!R:R,MATCH(A90,mapping!P:P,0),1)+INDEX(mapping!H:H,MATCH(E90,mapping!F:F,0)) -> 3006 | D90: Assists Per Game (361 ranked) | E90: Purdue | F90: 3 | G90: 1 | H90: 19.9 | I90: Cornell | J90: 21.3
A91: =IF(NOT(D91=""),INDEX(statsNames,MATCH(D91,mapping!Q:Q,0),1),A90) -> APG | B91: =INDEX(mapping!R:R,MATCH(A91,mapping!P:P,0),1)+INDEX(mapping!H:H,MATCH(E91,mapping!F:F,0)) -> 7606 | E91: Michigan | F91: 5 | G91: 2 | H91: 18.6
A92: =IF(NOT(D92=""),INDEX(statsNames,MATCH(D92,mapping!Q:Q,0),1),A91) -> APG | B92: =INDEX(mapping!R:R,MATCH(A92,mapping!P:P,0),1)+INDEX(mapping!H:H,MATCH(E92,mapping!F:F,0)) -> 906 | E92: Michigan St. | F92: 6 | G92: 3 | H92: 18.5
A93: =IF(NOT(D93=""),INDEX(statsNames,MATCH(D93,mapping!Q:Q,0),1),A92) -> APG | B93: =INDEX(mapping!R:R,MATCH(A93,mapping!P:P,0),1)+INDEX(mapping!H:H,MATCH(E93,mapping!F:F,0)) -> 8206 | E93: Akron | F93: 7 | G93: 1 | H93: 18.4
A94: =IF(NOT(D94=""),INDEX(statsNames,MATCH(D94,mapping!Q:Q,0),1),A93) -> APG | B94: =INDEX(mapping!R:R,MATCH(A94,mapping!P:P,0),1)+INDEX(mapping!H:H,MATCH(E94,mapping!F:F,0)) -> 17006 | E94: Utah Valley | F94: 8 | G94: 1 | H94: 18.4
A95: =IF(NOT(D95=""),INDEX(statsNames,MATCH(D95,mapping!Q:Q,0),1),A94) -> APG | B95: =INDEX(mapping!R:R,MATCH(A95,mapping!P:P,0),1)+INDEX(mapping!H:H,MATCH(E95,mapping!F:F,0)) -> 2306 | E95: UConn | F95: 9 | G95: 1 | H95: 18.4
A96: =IF(NOT(D96=""),INDEX(statsNames,MATCH(D96,mapping!Q:Q,0),1),A95) -> APG | B96: =INDEX(mapping!R:R,MATCH(A96,mapping!P:P,0),1)+INDEX(mapping!H:H,MATCH(E96,mapping!F:F,0)) -> 4406 | E96: Gonzaga | F96: 10 | G96: 1 | H96: 18.3
A97: =IF(NOT(D97=""),INDEX(statsNames,MATCH(D97,mapping!Q:Q,0),1),A96) -> APG | B97: =INDEX(mapping!R:R,MATCH(A97,mapping!P:P,0),1)+INDEX(mapping!H:H,MATCH(E97,mapping!F:F,0)) -> 16306 | E97: Saint Louis | F97: 10 | G97: 1 | H97: 18.3
A98: =IF(NOT(D98=""),INDEX(statsNames,MATCH(D98,mapping!Q:Q,0),1),A97) -> APG | B98: =INDEX(mapping!R:R,MATCH(A98,mapping!P:P,0),1)+INDEX(mapping!H:H,MATCH(E98,mapping!F:F,0)) -> 3606 | E98: Texas A&M | F98: 12 | G98: 1 | H98: 18.1
A99: =IF(NOT(D99=""),INDEX(statsNames,MATCH(D99,mapping!Q:Q,0),1),A98) -> APG | B99: =INDEX(mapping!R:R,MATCH(A99,mapping!P:P,0),1)+INDEX(mapping!H:H,MATCH(E99,mapping!F:F,0)) -> 7306 | E99: Nebraska | F99: 14 | G99: 4 | H99: 18
A100: =IF(NOT(D100=""),INDEX(statsNames,MATCH(D100,mapping!Q:Q,0),1),A99) -> APG | B100: =INDEX(mapping!R:R,MATCH(A100,mapping!P:P,0),1)+INDEX(mapping!H:H,MATCH(E100,mapping!F:F,0)) -> 15106 | E100: Robert Morris | F100: 16 | G100: 2 | H100: 17.7
A101: =IF(NOT(D101=""),INDEX(statsNames,MATCH(D101,mapping!Q:Q,0),1),A100) -> APG | B101: =INDEX(mapping!R:R,MATCH(A101,mapping!P:P,0),1)+INDEX(mapping!H:H,MATCH(E101,mapping!F:F,0)) -> 1406 | E101: Utah St. | F101: 17 | G101: 1 | H101: 17.6
A102: =IF(NOT(D102=""),INDEX(statsNames,MATCH(D102,mapping!Q:Q,0),1),A101) -> APG | B102: =INDEX(mapping!R:R,MATCH(A102,mapping!P:P,0),1)+INDEX(mapping!H:H,MATCH(E102,mapping!F:F,0)) -> 11206 | E102: South Fla. | F102: 21 | G102: 1 | H102: 17.3
... A176: =IF(NOT(D176=""),INDEX(statsNames,MATCH(D176,mapping!Q:Q,0),1),A175) -> APG | B176: =INDEX(mapping!R:R,MATCH(A176,mapping!P:P,0),1)+INDEX(mapping!H:H,MATCH(E176,mapping!F:F,0)) -> 8706 | E176: Stanford | F176: 318 | G176: 17 | H176: 11.9
A177: =IF(NOT(D177=""),INDEX(statsNames,MATCH(D177,mapping!Q:Q,0),1),A176) -> Bench | B177: =INDEX(mapping!R:R,MATCH(A177,mapping!P:P,0),1)+INDEX(mapping!H:H,MATCH(E177,mapping!F:F,0)) -> 3607 | D177: Bench Points per game (361 ranked) | E177: Texas A&M | F177: 2 | G177: 1 | H177: 35.56 | I177: Tarleton St. | J177: 37.31
A178: =IF(NOT(D178=""),INDEX(statsNames,MATCH(D178,mapping!Q:Q,0),1),A177) -> Bench | B178: =INDEX(mapping!R:R,MATCH(A178,mapping!P:P,0),1)+INDEX(mapping!H:H,MATCH(E178,mapping!F:F,0)) -> 1207 | E178: San Diego St. | F178: 3 | G178: 1 | H178: 35.39
A179: =IF(NOT(D179=""),INDEX(statsNames,MATCH(D179,mapping!Q:Q,0),1),A178) -> Bench | B179: =INDEX(mapping!R:R,MATCH(A179,mapping!P:P,0),1)+INDEX(mapping!H:H,MATCH(E179,mapping!F:F,0)) -> 4407 | E179: Gonzaga | F179: 5 | G179: 1 | H179: 34.73
A180: =IF(NOT(D180=""),INDEX(statsNames,MATCH(D180,mapping!Q:Q,0),1),A179) -> Bench | B180: =INDEX(mapping!R:R,MATCH(A180,mapping!P:P,0),1)+INDEX(mapping!H:H,MATCH(E180,mapping!F:F,0)) -> 13907 | E180: Georgia | F180: 6 | G180: 2 | H180: 34.13
A181: =IF(NOT(D181=""),INDEX(statsNames,MATCH(D181,mapping!Q:Q,0),1),A180) -> Bench | B181: =INDEX(mapping!R:R,MATCH(A181,mapping!P:P,0),1)+INDEX(mapping!H:H,MATCH(E181,mapping!F:F,0)) -> 12207 | E181: VCU | F181: 7 | G181: 1 | H181: 34
A182: =IF(NOT(D182=""),INDEX(statsNames,MATCH(D182,mapping!Q:Q,0),1),A181) -> Bench | B182: =INDEX(mapping!R:R,MATCH(A182,mapping!P:P,0),1)+INDEX(mapping!H:H,MATCH(E182,mapping!F:F,0)) -> 16307 | E182: Saint Louis | F182: 11 | G182: 2 | H182: 33.39
A183: =IF(NOT(D183=""),INDEX(statsNames,MATCH(D183,mapping!Q:Q,0),1),A182) -> Bench | B183: =INDEX(mapping!R:R,MATCH(A183,mapping!P:P,0),1)+INDEX(mapping!H:H,MATCH(E183,mapping!F:F,0)) -> 207 | E183: McNeese | F183: 19 | G183: 1 | H183: 30.76
A184: =IF(NOT(D184=""),INDEX(statsNames,MATCH(D184,mapping!Q:Q,0),1),A183) -> Bench | B184: =INDEX(mapping!R:R,MATCH(A184,mapping!P:P,0),1)+INDEX(mapping!H:H,MATCH(E184,mapping!F:F,0)) -> 10607 | E184: High Point | F184: 22 | G184: 2 | H184: 30.41
A185: =IF(NOT(D185=""),INDEX(statsNames,MATCH(D185,mapping!Q:Q,0),1),A184) -> Bench | B185: =INDEX(mapping!R:R,MATCH(A185,mapping!P:P,0),1)+INDEX(mapping!H:H,MATCH(E185,mapping!F:F,0)) -> 17807 | E185: Santa Clara | F185: 23 | G185: 2 | H185: 30.21
A186: =IF(NOT(D186=""),INDEX(statsNames,MATCH(D186,mapping!Q:Q,0),1),A185) -> Bench | B186: =INDEX(mapping!R:R,MATCH(A186,mapping!P:P,0),1)+INDEX(mapping!H:H,MATCH(E186,mapping!F:F,0)) -> 7607 | E186: Michigan | F186: 25 | G186: 1 | H186: 29.85
...

Sheet SODiv Index
A1: Conference | B1: SoD
A2: Big 12 | B2: 1
A3: Big Ten | B3: 1
A4: SEC | B4: 1
A5: Big East | B5: 0.95
A6: ACC | B6: 1
A7: MW | B7: 0.9
A8: American | B8: 0.7
A9: WCC | B9: 0.8
A10: A-10 | B10: 0.7
A11: C-USA | B11: 0.5
A12: MVC | B12: 0.5
A13: Ivy | B13: 0.5
... A32: SWAC | B32: 0.3

Sheet mapping
A1: BPI+ Value | B1: NET Map | C1: Count Check | D1: KP Map | E1: Count Check | F1: Stats Map | G1: Count Check | H1: ID | I1: INI | J1: ESPNimport | K1: ESPNimport2 | L1: Count Check | N1: Row Offset | P1: BPI+ Name | Q1: Stats Category | R1: Stat ID
A2: Miami | B2: Miami (FL) | C2: =COUNTIF('Net Import'!B:B,B2) -> 1 | D2: Miami FL | E2: =COUNTIF('KenPom import'!B:B,D2) -> 1 | F2: Miami (FL) | G2: =IF(COUNTIF('Stats import'!E:E,F2)>1,1,0) -> 1 | H2: 100 | I2: MIA | J2: =CONCATENATE(A2," ",INDEX(mascotCol,MATCH(A2,bpiTeams,0)),I2) -> Miami HurricanesMIA | K2: =CONCATENATE(A2," ",INDEX(mascotCol,MATCH(A2,bpiTeams,0)),A2," ",INDEX(mascotCol,MATCH(A2,bpiTeams,0))) -> Miami HurricanesMiami Hurricanes | L2: =COUNTIF(bpiImportCol,J2) -> 1 | N2: 367 | P2: 3PD% | Q2: Three Point Percentage Defense (361 ranked) | R2: 1
A3: McNeese | B3: McNeese | C3: =COUNTIF('Net Import'!B:B,B3) -> 1 | D3: McNeese | E3: =COUNTIF('KenPom import'!B:B,D3) -> 1 | F3: McNeese | G3: =IF(COUNTIF('Stats import'!E:E,F3)>1,1,0) -> 1 | H3: 200 | I3: MCN | J3: =CONCATENATE(A3," ",INDEX(mascotCol,MATCH(A3,bpiTeams,0)),I3) -> McNeese CowboysMCN | K3: =CONCATENATE(A3," ",INDEX(mascotCol,MATCH(A3,bpiTeams,0)),A3," ",INDEX(mascotCol,MATCH(A3,bpiTeams,0))) -> McNeese CowboysMcNeese Cowboys | L3: =COUNTIF(bpiImportCol,J3) -> 1 | P3: 3PPG | Q3: Three Pointers Per Game (361 ranked) | R3: 2
A4: Ole Miss | B4: Ole Miss | C4: =COUNTIF('Net Import'!B:B,B4) -> 1 | D4: Mississippi | E4: =COUNTIF('KenPom import'!B:B,D4) -> 1 | F4: Ole Miss | G4: =IF(COUNTIF('Stats import'!E:E,F4)>1,1,0) -> 0 | H4: 300 | I4: MISS | J4: =CONCATENATE(A4," ",INDEX(mascotCol,MATCH(A4,bpiTeams,0)),I4) -> #N/A | K4: =CONCATENATE(A4," ",INDEX(mascotCol,MATCH(A4,bpiTeams,0)),A4," ",INDEX(mascotCol,MATCH(A4,bpiTeams,0))) -> #N/A | L4: =COUNTIF(bpiImportCol,J4) -> 0 | N4: SOR Row Offset | P4: 3PT% | Q4: Three Point Percentage (361 ranked) | R4: 3
A5: Fort Wayne | B5: Purdue Fort Wayne | C5: =COUNTIF('Net Import'!B:B,B5) -> 1 | D5: Purdue Fort Wayne | E5: =COUNTIF('KenPom import'!B:B,D5) -> 1 | F5: Purdue Fort Wayne | G5: =IF(COUNTIF('Stats import'!E:E,F5)>1,1,0) -> 0 | H5: 400 | I5: PFW | J5: =CONCATENATE(A5," ",INDEX(mascotCol,MATCH(A5,bpiTeams,0)),I5) -> #N/A | K5: =CONCATENATE(A5," ",INDEX(mascotCol,MATCH(A5,bpiTeams,0)),A5," ",INDEX(mascotCol,MATCH(A5,bpiTeams,0))) -> #N/A | L5: =COUNTIF(bpiImportCol,J5) -> 0 | N5: 366 | P5: 3PTA | Q5: Three Point Attempts Per Game (361 ranked) | R5: 4
A6: Florida State | B6: Florida St. | C6: =COUNTIF('Net Import'!B:B,B6) -> 1 | D6: Florida St. | E6: =COUNTIF('KenPom import'!B:B,D6) -> 1 | F6: Florida St. | G6: =IF(COUNTIF('Stats import'!E:E,F6)>1,1,0) -> 0 | H6: 500 | I6: FSU | J6: =CONCATENATE(A6," ",INDEX(mascotCol,MATCH(A6,bpiTeams,0)),I6) -> #N/A | K6: =CONCATENATE(A6," ",INDEX(mascotCol,MATCH(A6,bpiTeams,0)),A6," ",INDEX(mascotCol,MATCH(A6,bpiTeams,0))) -> #N/A | L6: =COUNTIF(bpiImportCol,J6) -> 0 | P6: A:T | Q6: Assist/Turnover Ratio (361 ranked) | R6: 5
A7: Iowa State | B7: Iowa St. | C7: =COUNTIF('Net Import'!B:B,B7) -> 1 | D7: Iowa St. | E7: =COUNTIF('KenPom import'!B:B,D7) -> 1 | F7: Iowa St. | G7: =IF(COUNTIF('Stats import'!E:E,F7)>1,1,0) -> 1 | H7: 600 | I7: ISU | J7: =CONCATENATE(A7," ",INDEX(mascotCol,MATCH(A7,bpiTeams,0)),I7) -> Iowa State CyclonesISU | K7: =CONCATENATE(A7," ",INDEX(mascotCol,MATCH(A7,bpiTeams,0)),A7," ",INDEX(mascotCol,MATCH(A7,bpiTeams,0))) -> Iowa State CyclonesIowa State Cyclones | L7: =COUNTIF(bpiImportCol,J7) -> 1 | P7: APG | Q7: Assists Per Game (361 ranked) | R7: 6
A8: Kansas State | B8: Kansas St. | C8: =COUNTIF('Net Import'!B:B,B8) -> 1 | D8: Kansas St. | E8: =COUNTIF('KenPom import'!B:B,D8) -> 1 | F8: Kansas St. | G8: =IF(COUNTIF('Stats import'!E:E,F8)>1,1,0) -> 0 | H8: 700 | I8: KSU | J8: =CONCATENATE(A8," ",INDEX(mascotCol,MATCH(A8,bpiTeams,0)),I8) -> #N/A | K8: =CONCATENATE(A8," ",INDEX(mascotCol,MATCH(A8,bpiTeams,0)),A8," ",INDEX(mascotCol,MATCH(A8,bpiTeams,0))) -> #N/A | L8: =COUNTIF(bpiImportCol,J8) -> 0 | P8: Bench | Q8: Bench Points per game (350 ranked) | R8: 7
A9: Weber State | B9: Weber St. | C9: =COUNTIF('Net Import'!B:B,B9) -> 1 | D9: Weber St. | E9: =COUNTIF('KenPom import'!B:B,D9) -> 1 | F9: Weber St. | G9: =IF(COUNTIF('Stats import'!E:E,F9)>1,1,0) -> 0 | H9: 800 | I9: WEB | J9: =CONCATENATE(A9," ",INDEX(mascotCol,MATCH(A9,bpiTeams,0)),I9) -> #N/A | K9: =CONCATENATE(A9," ",INDEX(mascotCol,MATCH(A9,bpiTeams,0)),A9," ",INDEX(mascotCol,MATCH(A9,bpiTeams,0))) -> #N/A | L9: =COUNTIF(bpiImportCol,J9) -> 0 | P9: BPG | Q9: Blocks Per Game (361 ranked) | R9: 8
A10: Michigan State | B10: Michigan St. | C10: =COUNTIF('Net Import'!B:B,B10) -> 1 | D10: Michigan St. | E10: =COUNTIF('KenPom import'!B:B,D10) -> 1 | F10: Michigan St. | G10: =IF(COUNTIF('Stats import'!E:E,F10)>1,1,0) -> 1 | H10: 900 | I10: MSU | J10: =CONCATENATE(A10," ",INDEX(mascotCol,MATCH(A10,bpiTeams,0)),I10) -> Michigan State SpartansMSU | K10: =CONCATENATE(A10," ",INDEX(mascotCol,MATCH(A10,bpiTeams,0)),A10," ",INDEX(mascotCol,MATCH(A10,bpiTeams,0))) -> Michigan State SpartansMichigan State Spartans | L10: =COUNTIF(bpiImportCol,J10) -> 1 | P10: DFG% | Q10: Field Goal Percentage Defense (361 ranked) | R10: 9
A11: Ohio State | B11: Ohio St. | C11: =COUNTIF('Net Import'!B:B,B11) -> 1 | D11: Ohio St. | E11: =COUNTIF('KenPom import'!B:B,D11) -> 1 | F11: Ohio St. | G11: =IF(COUNTIF('Stats import'!E:E,F11)>1,1,0) -> 1 | H11: 1000 | I11: OSU | J11: =CONCATENATE(A11," ",INDEX(mascotCol,MATCH(A11,bpiTeams,0)),I11) -> Ohio State BuckeyesOSU | K11: =CONCATENATE(A11," ",INDEX(mascotCol,MATCH(A11,bpiTeams,0)),A11," ",INDEX(mascotCol,MATCH(A11,bpiTeams,0))) -> Ohio State BuckeyesOhio State Buckeyes | L11: =COUNTIF(bpiImportCol,J11) -> 1 | P11: DRPG | Q11: Rebounds (Defensive) Per Game (361 ranked) | R11: 10
A12: Indiana State | B12: Indiana St. | C12: =COUNTIF('Net Import'!B:B,B12) -> 1 | D12: Indiana St. | E12: =COUNTIF('KenPom import'!B:B,D12) -> 1 | F12: Indiana St. | G12: =IF(COUNTIF('Stats import'!E:E,F12)>1,1,0) -> 0 | H12: 1100 | I12: INST | J12: =CONCATENATE(A12," ",INDEX(mascotCol,MATCH(A12,bpiTeams,0)),I12) -> #N/A | K12: =CONCATENATE(A12," ",INDEX(mascotCol,MATCH(A12,bpiTeams,0)),A12," ",INDEX(mascotCol,MATCH(A12,bpiTeams,0))) -> #N/A | L12: =COUNTIF(bpiImportCol,J12) -> 0 | P12: EFG% | Q12: Effective FG pct (361 ranked) | R12: 11
A13: San Diego State | B13: San Diego St. | C13: =COUNTIF('Net Import'!B:B,B13) -> 1 | D13: San Diego St. | E13: =COUNTIF('KenPom import'!B:B,D13) -> 1 | F13: San Diego St. | G13: =IF(COUNTIF('Stats import'!E:E,F13)>1,1,0) -> 1 | H13: 1200 | I13: SDSU | J13: =CONCATENATE(A13," ",INDEX(mascotCol,MATCH(A13,bpiTeams,0)),I13) -> San Diego State AztecsSDSU | K13: =CONCATENATE(A13," ",INDEX(mascotCol,MATCH(A13,bpiTeams,0)),A13," ",INDEX(mascotCol,MATCH(A13,bpiTeams,0))) -> San Diego State AztecsSan Diego State Aztecs | L13: =COUNTIF(bpiImportCol,J13) -> 1 | P13: FB | Q13: Fastbreak Points (361 ranked) | R13: 12
A14: Colorado State | B14: Colorado St. | C14: =COUNTIF('Net Import'!B:B,B14) -> 1 | D14: Colorado St. | E14: =COUNTIF('KenPom import'!B:B,D14) -> 1 | F14: Colorado St. | G14: =IF(COUNTIF('Stats import'!E:E,F14)>1,1,0) -> 0 | H14: 1300 | I14: CSU | J14: =CONCATENATE(A14," ",INDEX(mascotCol,MATCH(A14,bpiTeams,0)),I14) -> #N/A | K14: =CONCATENATE(A14," ",INDEX(mascotCol,MATCH(A14,bpiTeams,0)),A14," ",INDEX(mascotCol,MATCH(A14,bpiTeams,0))) -> #N/A | L14: =COUNTIF(bpiImportCol,J14) -> 0 | P14: FG% | Q14: Field Goal Percentage (361 ranked) | R14: 13
A15: Utah State | B15: Utah St. | C15: =COUNTIF('Net Import'!B:B,B15) -> 1 | D15: Utah St. | E15: =COUNTIF('KenPom import'!B:B,D15) -> 1 | F15: Utah St. | G15: =IF(COUNTIF('Stats import'!E:E,F15)>1,1,0) -> 1 | H15: 1400 | I15: USU | J15: =CONCATENATE(A15," ",INDEX(mascotCol,MATCH(A15,bpiTeams,0)),I15) -> Utah State AggiesUSU | K15: =CONCATENATE(A15," ",INDEX(mascotCol,MATCH(A15,bpiTeams,0)),A15," ",INDEX(mascotCol,MATCH(A15,bpiTeams,0))) -> Utah State AggiesUtah State Aggies | L15: =COUNTIF(bpiImportCol,J15) -> 1 | P15: FPG | Q15: Fouls Per Game (361 ranked) | R15: 14
A16: Morehead State | B16: Morehead St. | C16: =COUNTIF('Net Import'!B:B,B16) -> 1 | D16: Morehead St. | E16: =COUNTIF('KenPom import'!B:B,D16) -> 1 | F16: Morehead St. | G16: =IF(COUNTIF('Stats import'!E:E,F16)>1,1,0) -> 0 | H16: 1500 | I16: MORE | J16: =CONCATENATE(A16," ",INDEX(mascotCol,MATCH(A16,bpiTeams,0)),I16) -> #N/A | K16: =CONCATENATE(A16," ",INDEX(mascotCol,MATCH(A16,bpiTeams,0)),A16," ",INDEX(mascotCol,MATCH(A16,bpiTeams,0))) -> #N/A | L16: =COUNTIF(bpiImportCol,J16) -> 0 | P16: FT% | Q16: Free Throw Percentage (361 ranked) | R16: 15
A17: Mississippi State | B17: Mississippi St. | C17: =COUNTIF('Net Import'!B:B,B17) -> 1 | D17: Mississippi St. | E17: =COUNTIF('KenPom import'!B:B,D17) -> 1 | F17: Mississippi St. | G17: =IF(COUNTIF('Stats import'!E:E,F17)>1,1,0) -> 0 | H17: 1600 | I17: MSST | J17: =CONCATENATE(A17," ",INDEX(mascotCol,MATCH(A17,bpiTeams,0)),I17) -> #N/A | K17: =CONCATENATE(A17," ",INDEX(mascotCol,MATCH(A17,bpiTeams,0)),A17," ",INDEX(mascotCol,MATCH(A17,bpiTeams,0))) -> #N/A | L17: =COUNTIF(bpiImportCol,J17) -> 0 | P17: FTA | Q17: Free Throw Attempts Per Game (361 ranked) | R17: 16
... A23: Florida Atlantic | B23: Fla. Atlantic | C23: =COUNTIF('Net Import'!B:B,B23) -> 1 | D23: Florida Atlantic | E23: =COUNTIF('KenPom import'!B:B,D23) -> 1 | F23: Fla. Atlantic | G23: =IF(COUNTIF('Stats import'!E:E,F23)>1,1,0) -> 0 | H23: 2200 | I23: FAU | J23: =CONCATENATE(A23," ",INDEX(mascotCol,MATCH(A23,bpiTeams,0)),I23) -> #N/A | K23: =CONCATENATE(A23," ",INDEX(mascotCol,MATCH(A23,bpiTeams,0)),A23," ",INDEX(mascotCol,MATCH(A23,bpiTeams,0))) -> #N/A | L23: =COUNTIF(bpiImportCol,J23) -> 0 | P23: RPG | Q23: Rebounds Per Game (361 ranked) | R23: 22
A24: Connecticut | B24: UConn | C24: =COUNTIF('Net Import'!B:B,B24) -> 1 | D24: Connecticut | E24: =COUNTIF('KenPom import'!B:B,D24) -> 1 | F24: UConn | G24: =IF(COUNTIF('Stats import'!E:E,F24)>1,1,0) -> 1 | H24: 2300 | I24: CONN | J24: UConn HuskiesCONN | K24: =CONCATENATE("UConn"," ",INDEX(mascotCol,MATCH(A24,bpiTeams,0)),"UConn"," ",INDEX(mascotCol,MATCH(A24,bpiTeams,0))) -> UConn HuskiesUConn Huskies | L24: =COUNTIF(bpiImportCol,J24) -> 1 | P24: SM | Q24: Scoring Margin (361 ranked) | R24: 23
A25: USC | B25: Southern California | C25: =COUNTIF('Net Import'!B:B,B25) -> 1 | D25: USC | E25: =COUNTIF('KenPom import'!B:B,D25) -> 1 | F25: Southern California | G25: =IF(COUNTIF('Stats import'!E:E,F25)>1,1,0) -> 1 | H25: 2400 | I25: USC | J25: =CONCATENATE(A25," ",INDEX(mascotCol,MATCH(A25,bpiTeams,0)),I25) -> #N/A | K25: =CONCATENATE(A25," ",INDEX(mascotCol,MATCH(A25,bpiTeams,0)),A25," ",INDEX(mascotCol,MATCH(A25,bpiTeams,0))) -> #N/A | L25: =COUNTIF(bpiImportCol,J25) -> 0 | P25: SPG | Q25: Steals Per Game (361 ranked) | R25: 24
A26: Saint Mary's | B26: Saint Mary's (CA) | C26: =COUNTIF('Net Import'!B:B,B26) -> 1 | D26: Saint Mary's | E26: =COUNTIF('KenPom import'!B:B,D26) -> 1 | F26: Saint Mary's (CA) | G26: =IF(COUNTIF('Stats import'!E:E,F26)>1,1,0) -> 1 | H26: 2500 | I26: SMC | J26: =CONCATENATE(A26," ",INDEX(mascotCol,MATCH(A26,bpiTeams,0)),I26) -> Saint Mary's GaelsSMC | K26: =CONCATENATE(A26," ",INDEX(mascotCol,MATCH(A26,bpiTeams,0)),A26," ",INDEX(mascotCol,MATCH(A26,bpiTeams,0))) -> Saint Mary's GaelsSaint Mary's Gaels | L26: =COUNTIF(bpiImportCol,J26) -> 1 | P26: TM | Q26: Turnover Margin (361 ranked) | R26: 25
A27: Virginia | B27: Virginia | C27: =COUNTIF('Net Import'!B:B,B27) -> 1 | D27: Virginia | E27: =COUNTIF('KenPom import'!B:B,D27) -> 1 | F27: Virginia | G27: =IF(COUNTIF('Stats import'!E:E,F27)>1,1,0) -> 1 | H27: 2600 | I27: UVA | J27: =CONCATENATE(A27," ",INDEX(mascotCol,MATCH(A27,bpiTeams,0)),I27) -> Virginia CavaliersUVA | K27: =CONCATENATE(A27," ",INDEX(mascotCol,MATCH(A27,bpiTeams,0)),A27," ",INDEX(mascotCol,MATCH(A27,bpiTeams,0))) -> Virginia CavaliersVirginia Cavaliers | L27: =COUNTIF(bpiImportCol,J27) -> 1 | P27: TOF | Q27: Turnovers Forced Per Game (361 ranked) | R27: 26
A28: BYU | B28: BYU | C28: =COUNTIF('Net Import'!B:B,B28) -> 1 | D28: BYU | E28: =COUNTIF('KenPom import'!B:B,D28) -> 1 | F28: BYU | G28: =IF(COUNTIF('Stats import'!E:E,F28)>1,1,0) -> 1 | H28: 2700 | I28: BYU | J28: =CONCATENATE(A28," ",INDEX(mascotCol,MATCH(A28,bpiTeams,0)),I28) -> BYU CougarsBYU | K28: =CONCATENATE(A28," ",INDEX(mascotCol,MATCH(A28,bpiTeams,0)),A28," ",INDEX(mascotCol,MATCH(A28,bpiTeams,0))) -> BYU CougarsBYU Cougars | L28: =COUNTIF(bpiImportCol,J28) -> 1 | P28: TPG | Q28: Turnovers Per Game (361 ranked) | R28: 27
A29: Houston | B29: Houston | C29: =COUNTIF('Net Import'!B:B,B29) -> 1 | D29: Houston | E29: =COUNTIF('KenPom import'!B:B,D29) -> 1 | F29: Houston | G29: =IF(COUNTIF('Stats import'!E:E,F29)>1,1,0) -> 1 | H29: 2800 | I29: HOU | J29: =CONCATENATE(A29," ",INDEX(mascotCol,MATCH(A29,bpiTeams,0)),I29) -> Houston CougarsHOU | K29: =CONCATENATE(A29," ",INDEX(mascotCol,MATCH(A29,bpiTeams,0)),A29," ",INDEX(mascotCol,MATCH(A29,bpiTeams,0))) -> Houston CougarsHouston Cougars | L29: =COUNTIF(bpiImportCol,J29) -> 1 | P29: Bench | Q29: Bench Points per game (361 ranked) | R29: 7
A30: Arizona | B30: Arizona | C30: =COUNTIF('Net Import'!B:B,B30) -> 1 | D30: Arizona | E30: =COUNTIF('KenPom import'!B:B,D30) -> 1 | F30: Arizona | G30: =IF(COUNTIF('Stats import'!E:E,F30)>1,1,0) -> 1 | H30: 2900 | I30: ARIZ | J30: =CONCATENATE(A30," ",INDEX(mascotCol,MATCH(A30,bpiTeams,0)),I30) -> Arizona WildcatsARIZ | K30: =CONCATENATE(A30," ",INDEX(mascotCol,MATCH(A30,bpiTeams,0)),A30," ",INDEX(mascotCol,MATCH(A30,bpiTeams,0))) -> Arizona WildcatsArizona Wildcats | L30: =COUNTIF(bpiImportCol,J30) -> 1 | P30: 3PT% | Q30: Three Point Percentage (360 ranked) | R30: 3
A31: Purdue | B31: Purdue | C31: =COUNTIF('Net Import'!B:B,B31) -> 1 | D31: Purdue | E31: =COUNTIF('KenPom import'!B:B,D31) -> 1 | F31: Purdue | G31: =IF(COUNTIF('Stats import'!E:E,F31)>1,1,0) -> 1 | H31: 3000 | I31: PUR | J31: =CONCATENATE(A31," ",INDEX(mascotCol,MATCH(A31,bpiTeams,0)),I31) -> Purdue BoilermakersPUR | K31: =CONCATENATE(A31," ",INDEX(mascotCol,MATCH(A31,bpiTeams,0)),A31," ",INDEX(mascotCol,MATCH(A31,bpiTeams,0))) -> Purdue BoilermakersPurdue Boilermakers | L31: =COUNTIF(bpiImportCol,J31) -> 1
A32: Creighton | B32: Creighton | C32: =COUNTIF('Net Import'!B:B,B32) -> 1 | D32: Creighton | E32: =COUNTIF('KenPom import'!B:B,D32) -> 1 | F32: Creighton | G32: =IF(COUNTIF('Stats import'!E:E,F32)>1,1,0) -> 0 | H32: 3100 | I32: CREI | J32: =CONCATENATE(A32," ",INDEX(mascotCol,MATCH(A32,bpiTeams,0)),I32) -> #N/A | K32: =CONCATENATE(A32," ",INDEX(mascotCol,MATCH(A32,bpiTeams,0)),A32," ",INDEX(mascotCol,MATCH(A32,bpiTeams,0))) -> #N/A | L32: =COUNTIF(bpiImportCol,J32) -> 0
A33: Baylor | B33: Baylor | C33: =COUNTIF('Net Import'!B:B,B33) -> 1 | D33: Baylor | E33: =COUNTIF('KenPom import'!B:B,D33) -> 1 | F33: Baylor | G33: =IF(COUNTIF('Stats import'!E:E,F33)>1,1,0) -> 0 | H33: 3200 | I33: BAY | J33: =CONCATENATE(A33," ",INDEX(mascotCol,MATCH(A33,bpiTeams,0)),I33) -> #N/A | K33: =CONCATENATE(A33," ",INDEX(mascotCol,MATCH(A33,bpiTeams,0)),A33," ",INDEX(mascotCol,MATCH(A33,bpiTeams,0))) -> #N/A | L33: =COUNTIF(bpiImportCol,J33) -> 0
A34: Marquette | B34: Marquette | C34: =COUNTIF('Net Import'!B:B,B34) -> 1 | D34: Marquette | E34: =COUNTIF('KenPom import'!B:B,D34) -> 1 | F34: Marquette | G34: =IF(COUNTIF('Stats import'!E:E,F34)>1,1,0) -> 0 | H34: 3300 | I34: MARQ | J34: =CONCATENATE(A34," ",INDEX(mascotCol,MATCH(A34,bpiTeams,0)),I34) -> #N/A | K34: =CONCATENATE(A34," ",INDEX(mascotCol,MATCH(A34,bpiTeams,0)),A34," ",INDEX(mascotCol,MATCH(A34,bpiTeams,0))) -> #N/A | L34: =COUNTIF(bpiImportCol,J34) -> 0
A35: Princeton | B35: Princeton | C35: =COUNTIF('Net Import'!B:B,B35) -> 1 | D35: Princeton | E35: =COUNTIF('KenPom import'!B:B,D35) -> 1 | F35: Princeton | G35: =IF(COUNTIF('Stats import'!E:E,F35)>1,1,0) -> 0 | H35: 3400 | I35: PRIN | J35: =CONCATENATE(A35," ",INDEX(mascotCol,MATCH(A35,bpiTeams,0)),I35) -> #N/A | K35: =CONCATENATE(A35," ",INDEX(mascotCol,MATCH(A35,bpiTeams,0)),A35," ",INDEX(mascotCol,MATCH(A35,bpiTeams,0))) -> #N/A | L35: =COUNTIF(bpiImportCol,J35) -> 0
A36: Tennessee | B36: Tennessee | C36: =COUNTIF('Net Import'!B:B,B36) -> 1 | D36: Tennessee | E36: =COUNTIF('KenPom import'!B:B,D36) -> 1 | F36: Tennessee | G36: =IF(COUNTIF('Stats import'!E:E,F36)>1,1,0) -> 1 | H36: 3500 | I36: TENN | J36: =CONCATENATE(A36," ",INDEX(mascotCol,MATCH(A36,bpiTeams,0)),I36) -> Tennessee VolunteersTENN | K36: =CONCATENATE(A36," ",INDEX(mascotCol,MATCH(A36,bpiTeams,0)),A36," ",INDEX(mascotCol,MATCH(A36,bpiTeams,0))) -> Tennessee VolunteersTennessee Volunteers | L36: =COUNTIF(bpiImportCol,J36) -> 1
A37: Texas A&M | B37: Texas A&M | C37: =COUNTIF('Net Import'!B:B,B37) -> 1 | D37: Texas A&M | E37: =COUNTIF('KenPom import'!B:B,D37) -> 1 | F37: Texas A&M | G37: =IF(COUNTIF('Stats import'!E:E,F37)>1,1,0) -> 1 | H37: 3600 | I37: TA&M | J37: =CONCATENATE(A37," ",INDEX(mascotCol,MATCH(A37,bpiTeams,0)),I37) -> Texas A&M AggiesTA&M | K37: =CONCATENATE(A37," ",INDEX(mascotCol,MATCH(A37,bpiTeams,0)),A37," ",INDEX(mascotCol,MATCH(A37,bpiTeams,0))) -> Texas A&M AggiesTexas A&M Aggies | L37: =COUNTIF(bpiImportCol,J37) -> 1
A38: Alabama | B38: Alabama | C38: =COUNTIF('Net Import'!B:B,B38) -> 1 | D38: Alabama | E38: =COUNTIF('KenPom import'!B:B,D38) -> 1 | F38: Alabama | G38: =IF(COUNTIF('Stats import'!E:E,F38)>1,1,0) -> 1 | H38: 3700 | I38: ALA | J38: =CONCATENATE(A38," ",INDEX(mascotCol,MATCH(A38,bpiTeams,0)),I38) -> Alabama Crimson TideALA | K38: =CONCATENATE(A38," ",INDEX(mascotCol,MATCH(A38,bpiTeams,0)),A38," ",INDEX(mascotCol,MATCH(A38,bpiTeams,0))) -> Alabama Crimson TideAlabama Crimson Tide | L38: =COUNTIF(bpiImportCol,J38) -> 1
A39: Oklahoma | B39: Oklahoma | C39: =COUNTIF('Net Import'!B:B,B39) -> 1 | D39: Oklahoma | E39: =COUNTIF('KenPom import'!B:B,D39) -> 1 | F39: Oklahoma | G39: =IF(COUNTIF('Stats import'!E:E,F39)>1,1,0) -> 1 | H39: 3800 | I39: OU | J39: =CONCATENATE(A39," ",INDEX(mascotCol,MATCH(A39,bpiTeams,0)),I39) -> Oklahoma SoonersOU | K39: =CONCATENATE(A39," ",INDEX(mascotCol,MATCH(A39,bpiTeams,0)),A39," ",INDEX(mascotCol,MATCH(A39,bpiTeams,0))) -> Oklahoma SoonersOklahoma Sooners | L39: =COUNTIF(bpiImportCol,J39) -> 1
A40: Kansas | B40: Kansas | C40: =COUNTIF('Net Import'!B:B,B40) -> 1 | D40: Kansas | E40: =COUNTIF('KenPom import'!B:B,D40) -> 1 | F40: Kansas | G40: =IF(COUNTIF('Stats import'!E:E,F40)>1,1,0) -> 1 | H40: 3900 | I40: KU | J40: =CONCATENATE(A40," ",INDEX(mascotCol,MATCH(A40,bpiTeams,0)),I40) -> Kansas JayhawksKU | K40: =CONCATENATE(A40," ",INDEX(mascotCol,MATCH(A40,bpiTeams,0)),A40," ",INDEX(mascotCol,MATCH(A40,bpiTeams,0))) -> Kansas JayhawksKansas Jayhawks | L40: =COUNTIF(bpiImportCol,J40) -> 1
A41: Clemson | B41: Clemson | C41: =COUNTIF('Net Import'!B:B,B41) -> 1 | D41: Clemson | E41: =COUNTIF('KenPom import'!B:B,D41) -> 1 | F41: Clemson | G41: =IF(COUNTIF('Stats import'!E:E,F41)>1,1,0) -> 1 | H41: 4000 | I41: CLEM | J41: =CONCATENATE(A41," ",INDEX(mascotCol,MATCH(A41,bpiTeams,0)),I41) -> Clemson TigersCLEM | K41: =CONCATENATE(A41," ",INDEX(mascotCol,MATCH(A41,bpiTeams,0)),A41," ",INDEX(mascotCol,MATCH(A41,bpiTeams,0))) -> Clemson TigersClemson Tigers | L41: =COUNTIF(bpiImportCol,J41) -> 1
A42: Cincinnati | B42: Cincinnati | C42: =COUNTIF('Net Import'!B:B,B42) -> 1 | D42: Cincinnati | E42: =COUNTIF('KenPom import'!B:B,D42) -> 1 | F42: Cincinnati | G42: =IF(COUNTIF('Stats import'!E:E,F42)>1,1,0) -> 1 | H42: 4100 | I42: CIN | J42: =CONCATENATE(A42," ",INDEX(mascotCol,MATCH(A42,bpiTeams,0)),I42) -> Cincinnati BearcatsCIN | K42: =CONCATENATE(A42," ",INDEX(mascotCol,MATCH(A42,bpiTeams,0)),A42," ",INDEX(mascotCol,MATCH(A42,bpiTeams,0))) -> Cincinnati BearcatsCincinnati Bearcats | L42: =COUNTIF(bpiImportCol,J42) -> 1
... A110: Oakland | B110: Oakland | C110: =COUNTIF('Net Import'!B:B,B110) -> 1 | D110: Oakland | E110: =COUNTIF('KenPom import'!B:B,D110) -> 1 | F110: Oakland | G110: =IF(COUNTIF('Stats import'!E:E,F110)>1,1,0) -> 0 | H110: 10900 | I110: OAK | J110: =CONCATENATE(A110," ",INDEX(mascotCol,MATCH(A110,bpiTeams,0)),I110) -> #N/A | K110: =CONCATENATE(A110," ",INDEX(mascotCol,MATCH(A110,bpiTeams,0)),A110," ",INDEX(mascotCol,MATCH(A110,bpiTeams,0))) -> #N/A | L110: =COUNTIF(bpiImportCol,J110) -> 0
A111: Quinnipiac | B111: =A111 -> Quinnipiac | C111: =COUNTIF('Net Import'!B:B,B111) -> 1 | D111: =A111 -> Quinnipiac | E111: =COUNTIF('KenPom import'!B:B,D111) -> 1 | F111: =A111 -> Quinnipiac | G111: =IF(COUNTIF('Stats import'!E:E,F111)>1,1,0) -> 0 | H111: =H110+100 -> 11000 | I111: QUIN | J111: =CONCATENATE(A111," ",INDEX(mascotCol,MATCH(A111,bpiTeams,0)),I111) -> #N/A | K111: =CONCATENATE(A111," ",INDEX(mascotCol,MATCH(A111,bpiTeams,0)),A111," ",INDEX(mascotCol,MATCH(A111,bpiTeams,0))) -> #N/A | L111: =COUNTIF(bpiImportCol,J111) -> 0
A112: Maryland | B112: =A112 -> Maryland | C112: =COUNTIF('Net Import'!B:B,B112) -> 1 | D112: =A112 -> Maryland | E112: =COUNTIF('KenPom import'!B:B,D112) -> 1 | F112: =A112 -> Maryland | G112: =IF(COUNTIF('Stats import'!E:E,F112)>1,1,0) -> 0 | H112: =H111+100 -> 11100 | I112: MD | J112: =CONCATENATE(A112," ",INDEX(mascotCol,MATCH(A112,bpiTeams,0)),I112) -> #N/A | K112: =CONCATENATE(A112," ",INDEX(mascotCol,MATCH(A112,bpiTeams,0)),A112," ",INDEX(mascotCol,MATCH(A112,bpiTeams,0))) -> #N/A | L112: =COUNTIF(bpiImportCol,J112) -> 0
...

Sheet BPI+
A1: Rank* | B1: Conf* | C1: Team* | D1: Mascot* | E1: Seed* | F1: Conf* | G1: Next* | H1: BPI | I1: NET | J1: SOR | K1: AP* | L1: BKTLGY* | M1: OVR | N1: In 50 | O1: BPI Val | P1: KP Off | Q1: KP Def | R1: Res. | S1: L8 W | T1: L8 L | U1: QW | V1: QL | W1: TL | X1: FILL | Y1: RW | Z1: RW | AA1: RW | AB1: RW | AC1: RW | AD1: RW | AE1: RW | AF1: RW | AG1: RW | AH1: RW | AI1: RW | AJ1: RW | AK1: RL | AL1: RL | AM1: RL | AN1: RL | AO1: RL | AP1: RL | AQ1: RL | AR1: RL | AS1: RL | AT1: RL | AU1: RL | AV1: RL | AW1: QW | AX1: QW | AY1: QW | AZ1: QW | BA1: QW | BB1: QW | BC1: QW | BD1: QW | BE1: QW | BF1: QW | BG1: QW | BH1: QW | BI1: QW | BJ1: QW | BK1: QW | BL1: QL | BM1: QL | BN1: QL | BO1: QL | BP1: QL | BQ1: QL | BR1: QL | BS1: QL | BT1: QL | BU1: QL | BV1: QL | BW1: QL | BX1: QL | BY1: NL | BZ1: NL | CA1: NL | CB1: NL | CC1: NL | CD1: NL | CE1: NL | CF1: NL | CG1: NL | CH1: NL | CI1: NL | CJ1: NL | CK1: NL | CL1: NL | CM1: NL | CN1: NL | CO1: NL | CP1: NL | CQ1: NL | CR1: NL | CS1: NL | CT1: BSR | CU1: Part 1 | CV1: SoD | CW1: Part 2 | CX1: A:T | CY1: APG | CZ1: Bench | DA1: BPG | DB1: EFG% | DC1: FB | DD1: FG% | DE1: DFG% | DF1: FPG | DG1: FTA | DH1: FT% | DI1: FTPG | DJ1: RM | DK1: DRPG | DL1: ORPG | DM1: RPG | DN1: OPPG | DO1: SM | DP1: PPG | DQ1: SPG | DR1: 3PTA | DS1: 3PT% | DT1: 3PD% | DU1: 3PPG | DV1: TM | DW1: TOF | DX1: TPG | DY1: Blank | DZ1: Res | EA1: BPI | EB1: Tempo | EC1: A:T | ED1: APG | EE1: Bench | EF1: BPG | EG1: EFG% | EH1: FB | EI1: FG% | EJ1: DFG% | EK1: FPG | EL1: FTA | EM1: FT% | EN1: FTPG | EO1: RM | EP1: DRPG | EQ1: ORPG | ER1: RPG | ES1: OPPG | ET1: SM | EU1: PPG | EV1: SPG | EW1: 3PTA | EX1: 3PT% | EY1: 3PD% | EZ1: 3PPG | FA1: TM | FB1: TOF | FC1: TPG | FD1: Res | FE1: BPI | FF1: Tempo | FG1: 2PTA | FH1: %3PTA | GQ1: Up to: | GR1: 46093
A2: 1 | B2: Big 12 | C2: Arizona | D2: Wildcats | E2: 1 | F2: WIN | H2: =_xlfn.IFNA(INDEX(importBPIRkCol,MATCH(INDEX(espnMap,MATCH(C2,valCol,0)),bpiImportCol,0)+rowOffset),INDEX(importBPIRkCol,MATCH(INDEX(espnMap2,MATCH(C2,valCol,0)),bpiImportCol,0)+rowOffset)) -> 3 | I2: =IFERROR(INDEX('Net Import'!A:A,MATCH(INDEX(mapping!B:B,MATCH(C2,mapping!A:A,0),1),'Net Import'!B:B,0),1),0) -> 3 | J2: =_xlfn.IFNA(INDEX(sorRkCol,MATCH(INDEX(espnMap,MATCH(C2,valCol,0)),sorTeamCol,0)+sorRowOffset),INDEX(sorRkCol,MATCH(INDEX(espnMap2,MATCH(C2,valCol,0)),sorTeamCol,0)+sorRowOffset)) -> 1 | K2: 2 | L2: 1.5 | M2: =CW2+R2*1.8+IF(K2>0,K2-26,0)/2+IF(CV2>0.5,0,10)-0.5*O2-IF(F2="WIN",1,IF(F2="IN",0.5,0))-S2+IF(W2>13.5,2,0)-IF(W2<6,6-W2,0) -> -73.058308 | N2: =IF(COUNTIF(H2:J2,"<50.5")>1.5,1,0) -> 1 | O2: =_xlfn.IFNA(INDEX(importBPICol,MATCH(INDEX(espnMap,MATCH(C2,valCol,0)),bpiImportCol,0)+rowOffset), INDEX(importBPICol,MATCH(INDEX(espnMap2,MATCH(C2,valCol,0)),bpiImportCol,0)+rowOffset)) -> 23.7 | P2: =INDEX(kpOff,MATCH(INDEX(kpVal,MATCH(C2,valCol,0)),kpTeam,0)) -> 7 | Q2: =INDEX(kpDef,MATCH(INDEX(kpVal,MATCH(C2,valCol,0)),kpTeam,0)) -> 3 | R2: =-1*INDEX(calculatedResVal,MATCH(C2,resValueTeamCol,0)) -> -21.204615 | S2: 8 | T2: 0 | U2: =COUNTA(AW2:BK2)+COUNTA(Y2:AJ2) -> 18 | V2: =COUNTA(BL2:BX2)+COUNTA(AK2:AV2) -> 2 | W2: =COUNTA(AK2:AV2)+COUNTA(BL2:CS2) -> 2 | X2: =IF(SUM(S2:W2)>0,1,0) -> 1 | Y2: FLA | Z2: UCLA | AA2: CONN | AB2: AUB | AC2: ALA | AD2: BYU | AE2: BYU | AF2: HOU | AG2: KU | AH2: ISU | AI2: ISU | AJ2: HOU | AK2: KU | AL2: TTU | AW2: SDSU | AX2: TCU | AY2: UCF | AZ2: WVU | BA2: CIN | BB2: UCF | CT2: =H2*0.4+J2*1.2+I2*0.8 -> 4.8 | CU2: =CT2/2.4 -> 2 | CV2: =VLOOKUP(B2,'SODiv Index'!A:B,2,FALSE) -> 1 | CW2: =CU2*(10-CV2/5)/10 -> 1.96 | CX2: =INDEX('Stats import'!H:H,MATCH((INDEX(mapping!R:R,MATCH(INDEX(statsCategories,1,1),mapping!P:P,0),1)+INDEX(mapping!H:H,MATCH(C2,mapping!A:A,0),1)),'Stats import'!B:B,0),1) -> 1.57 | CY2: =INDEX('Stats import'!H:H,MATCH((INDEX(mapping!R:R,MATCH(INDEX(statsCategories,1,2),mapping!P:P,0),1)+INDEX(mapping!H:H,MATCH(C2,mapping!A:A,0),1)),'Stats import'!B:B,0),1) -> 16.9 | CZ2: =INDEX('Stats import'!H:H,MATCH((INDEX(mapping!R:R,MATCH(INDEX(statsCategories,1,3),mapping!P:P,0),1)+INDEX(mapping!H:H,MATCH(C2,mapping!A:A,0),1)),'Stats import'!B:B,0),1) -> 23.32 | DA2: =INDEX('Stats import'!H:H,MATCH((INDEX(mapping!R:R,MATCH(INDEX(statsCategories,1,4),mapping!P:P,0),1)+INDEX(mapping!H:H,MATCH(C2,mapping!A:A,0),1)),'Stats import'!B:B,0),1) -> 4.2 | DB2: =INDEX('Stats import'!H:H,MATCH((INDEX(mapping!R:R,MATCH(INDEX(statsCategories,1,5),mapping!P:P,0),1)+INDEX(mapping!H:H,MATCH(C2,mapping!A:A,0),1)),'Stats import'!B:B,0),1) -> 0.551 | DC2: =INDEX('Stats import'!H:H,MATCH((INDEX(mapping!R:R,MATCH(INDEX(statsCategories,1,6),mapping!P:P,0),1)+INDEX(mapping!H:H,MATCH(C2,mapping!A:A,0),1)),'Stats import'!B:B,0),1) -> 15.53 | DD2: =INDEX('Stats import'!H:H,MATCH((INDEX(mapping!R:R,MATCH(INDEX(statsCategories,1,7),mapping!P:P,0),1)+INDEX(mapping!H:H,MATCH(C2,mapping!A:A,0),1)),'Stats import'!B:B,0),1) -> 50.2 | DE2: =INDEX('Stats import'!H:H,MATCH((INDEX(mapping!R:R,MATCH(INDEX(statsCategories,1,8),mapping!P:P,0),1)+INDEX(mapping!H:H,MATCH(C2,mapping!A:A,0),1)),'Stats import'!B:B,0),1) -> 39.2 | DF2: =INDEX('Stats import'!H:H,MATCH((INDEX(mapping!R:R,MATCH(INDEX(statsCategories,1,9),mapping!P:P,0),1)+INDEX(mapping!H:H,MATCH(C2,mapping!A:A,0),1)),'Stats import'!B:B,0),1) -> 16 | DG2: =INDEX('Stats import'!H:H,MATCH((INDEX(mapping!R:R,MATCH(INDEX(statsCategories,1,10),mapping!P:P,0),1)+INDEX(mapping!H:H,MATCH(C2,mapping!A:A,0),1)),'Stats import'!B:B,0),1) -> 26.1 | DH2: =INDEX('Stats import'!H:H,MATCH((INDEX(mapping!R:R,MATCH(INDEX(statsCategories,1,11),mapping!P:P,0),1)+INDEX(mapping!H:H,MATCH(C2,mapping!A:A,0),1)),'Stats import'!B:B,0),1) -> 73.4 | DI2: =INDEX('Stats import'!H:H,MATCH((INDEX(mapping!R:R,MATCH(INDEX(statsCategories,1,12),mapping!P:P,0),1)+INDEX(mapping!H:H,MATCH(C2,mapping!A:A,0),1)),'Stats import'!B:B,0),1) -> 19.1 | DJ2: =INDEX('Stats import'!H:H,MATCH((INDEX(mapping!R:R,MATCH(INDEX(statsCategories,1,13),mapping!P:P,0),1)+INDEX(mapping!H:H,MATCH(C2,mapping!A:A,0),1)),'Stats import'!B:B,0),1) -> 10.8 | DK2: =INDEX('Stats import'!H:H,MATCH((INDEX(mapping!R:R,MATCH(INDEX(statsCategories,1,14),mapping!P:P,0),1)+INDEX(mapping!H:H,MATCH(C2,mapping!A:A,0),1)),'Stats import'!B:B,0),1) -> 29.76 | DL2: =INDEX('Stats import'!H:H,MATCH((INDEX(mapping!R:R,MATCH(INDEX(statsCategories,1,15),mapping!P:P,0),1)+INDEX(mapping!H:H,MATCH(C2,mapping!A:A,0),1)),'Stats import'!B:B,0),1) -> 12.76 | DM2: =INDEX('Stats import'!H:H,MATCH((INDEX(mapping!R:R,MATCH(INDEX(statsCategories,1,16),mapping!P:P,0),1)+INDEX(mapping!H:H,MATCH(C2,mapping!A:A,0),1)),'Stats import'!B:B,0),1) -> 42.53 | DN2: =INDEX('Stats import'!H:H,MATCH((INDEX(mapping!R:R,MATCH(INDEX(statsCategories,1,17),mapping!P:P,0),1)+INDEX(mapping!H:H,MATCH(C2,mapping!A:A,0),1)),'Stats import'!B:B,0),1) -> 68.8 | DO2: =INDEX('Stats import'!H:H,MATCH((INDEX(mapping!R:R,MATCH(INDEX(statsCategories,1,18),mapping!P:P,0),1)+INDEX(mapping!H:H,MATCH(C2,mapping!A:A,0),1)),'Stats import'!B:B,0),1) -> 17.4 | DP2: =INDEX('Stats import'!H:H,MATCH((INDEX(mapping!R:R,MATCH(INDEX(statsCategories,1,19),mapping!P:P,0),1)+INDEX(mapping!H:H,MATCH(C2,mapping!A:A,0),1)),'Stats import'!B:B,0),1) -> 86.1 | DQ2: =INDEX('Stats import'!H:H,MATCH((INDEX(mapping!R:R,MATCH(INDEX(statsCategories,1,20),mapping!P:P,0),1)+INDEX(mapping!H:H,MATCH(C2,mapping!A:A,0),1)),'Stats import'!B:B,0),1) -> 7.8 | DR2: =INDEX('Stats import'!H:H,MATCH((INDEX(mapping!R:R,MATCH(INDEX(statsCategories,1,21),mapping!P:P,0),1)+INDEX(mapping!H:H,MATCH(C2,mapping!A:A,0),1)),'Stats import'!B:B,0),1) -> 16.3 | DS2: =INDEX('Stats import'!H:H,MATCH((INDEX(mapping!R:R,MATCH(INDEX(statsCategories,1,22),mapping!P:P,0),1)+INDEX(mapping!H:H,MATCH(C2,mapping!A:A,0),1)),'Stats import'!B:B,0),1) -> 36 | DT2: =INDEX('Stats import'!H:H,MATCH((INDEX(mapping!R:R,MATCH(INDEX(statsCategories,1,23),mapping!P:P,0),1)+INDEX(mapping!H:H,MATCH(C2,mapping!A:A,0),1)),'Stats import'!B:B,0),1) -> 31.4 | DU2: =INDEX('Stats import'!H:H,MATCH((INDEX(mapping!R:R,MATCH(INDEX(statsCategories,1,24),mapping!P:P,0),1)+INDEX(mapping!H:H,MATCH(C2,mapping!A:A,0),1)),'Stats import'!B:B,0),1) -> 5.9 | DV2: =INDEX('Stats import'!H:H,MATCH((INDEX(mapping!R:R,MATCH(INDEX(statsCategories,1,25),mapping!P:P,0),1)+INDEX(mapping!H:H,MATCH(C2,mapping!A:A,0),1)),'Stats import'!B:B,0),1) -> 1.1 | DW2: =INDEX('Stats import'!H:H,MATCH((INDEX(mapping!R:R,MATCH(INDEX(statsCategories,1,26),mapping!P:P,0),1)+INDEX(mapping!H:H,MATCH(C2,mapping!A:A,0),1)),'Stats import'!B:B,0),1) -> 11.97 | DX2: =INDEX('Stats import'!H:H,MATCH((INDEX(mapping!R:R,MATCH(INDEX(statsCategories,1,27),mapping!P:P,0),1)+INDEX(mapping!H:H,MATCH(C2,mapping!A:A,0),1)),'Stats import'!B:B,0),1) -> 10.8 | DZ2: =R2 -> -21.204615 | EA2: =-O2 -> -23.7 | EB2: =INDEX('KenPom import'!J:J,MATCH(INDEX(kpVal,MATCH(C2,valCol,0)),kpTeam,0)) -> 70.1 | EC2: =(CX2-INDEX(FK:FK,4,1))/INDEX(FK:FK,3,1) -> 0.51975982 | ED2: =(CY2-INDEX(FL:FL,4,1))/INDEX(FL:FL,3,1) -> 0.80246063 | EE2: =(CZ2-INDEX(FM:FM,4,1))/INDEX(FM:FM,3,1) -> 0.25920915 | EF2: =(DA2-INDEX(FN:FN,4,1))/INDEX(FN:FN,3,1) -> 0.45710074 | EG2: =(DB2-INDEX(FO:FO,4,1))/INDEX(FO:FO,3,1) -> 0.41126913 | EH2: =(DC2-INDEX(FP:FP,4,1))/INDEX(FP:FP,3,1) -> 1.3167282 | EI2: =(DD2-INDEX(FQ:FQ,4,1))/INDEX(FQ:FQ,3,1) -> 1.6059508 | EJ2: =(DE2-INDEX(FR:FR,4,1))/INDEX(FR:FR,3,1)*-1 -> 1.6455587 | EK2: =(DF2-INDEX(FS:FS,4,1))/INDEX(FS:FS,3,1)*-1 -> 0.71319785 | EL2: =(DG2-INDEX(FT:FT,4,1))/INDEX(FT:FT,3,1) -> 1.6080803 | EM2: =(DH2-INDEX(FU:FU,4,1))/INDEX(FU:FU,3,1) -> -0.073142648 | EN2: =(DI2-INDEX(FV:FV,4,1))/INDEX(FV:FV,3,1) -> 1.4833657 | EO2: =(DJ2-INDEX(FW:FW,4,1))/INDEX(FW:FW,3,1) -> 1.9709141 | EP2: =(DK2-INDEX(FX:FX,4,1))/INDEX(FX:FX,3,1) -> 2.3297549 | EQ2: =(DL2-INDEX(FY:FY,4,1))/INDEX(FY:FY,3,1) -> 0.76767608 | ER2: =(DM2-INDEX(FZ:FZ,4,1))/INDEX(FZ:FZ,3,1) -> 2.0433399 | ES2: =(DN2-INDEX(GA:GA,4,1))/INDEX(GA:GA,3,1)*-1 -> 0.58531398 | ET2: =(DO2-INDEX(GB:GB,4,1))/INDEX(GB:GB,3,1) -> 1.8600473 | EU2: =(DP2-INDEX(GC:GC,4,1))/INDEX(GC:GC,3,1) -> 1.0806672 | EV2: =(DQ2-INDEX(GD:GD,4,1))/INDEX(GD:GD,3,1) -> 0.5807823 | EW2: =(DR2-INDEX(GE:GE,4,1))/INDEX(GE:GE,3,1) -> -1.9817705 | EX2: =(DS2-INDEX(GF:GF,4,1))/INDEX(GF:GF,3,1) -> 0.31312987 | EY2: =(DT2-INDEX(GG:GG,4,1))/INDEX(GG:GG,3,1)*-1 -> 0.63132928 | EZ2: =(DU2-INDEX(GH:GH,4,1))/INDEX(GH:GH,3,1) -> -1.7028449 | FA2: =(DV2-INDEX(GI:GI,4,1))/INDEX(GI:GI,3,1) -> -0.13666784 | FB2: =(DW2-INDEX(GJ:GJ,4,1))/INDEX(GJ:GJ,3,1) -> -0.090011201 | FC2: =(DX2-INDEX(GK:GK,4,1))/INDEX(GK:GK,3,1)*-1 -> -0.04227376 | FD2: =(DZ2-INDEX(GM:GM,4,1))/INDEX(GM:GM,3,1)*-1 -> 2.7974847 | FE2: =(EA2-INDEX(GN:GN,4,1))/INDEX(GN:GN,3,1)*-1 -> 1.6064764 | FF2: =(EB2-INDEX(GO:GO,4,1))/INDEX(GO:GO,3,1) -> 1.0147206 | FG2: =(((DP2-DI2-3*DU2)/2)+1.5*DU2)/DB2-DR2 -> 44.498548 | FH2: =DR2/(DR2+FG2) -> 0.26809851 | FK2: A:T | FL2: APG | FM2: Bench | FN2: BPG | FO2: EFG% | FP2: FB | FQ2: FG% | FR2: DFG% | FS2: FPG | FT2: FTA | FU2: FT% | FV2: FTPG | FW2: RM | FX2: DRPG | FY2: ORPG | FZ2: RPG | GA2: OPPG | GB2: SM | GC2: PPG | GD2: SPG | GE2: 3PTA | GF2: 3PT% | GG2: 3PD% | GH2: 3PPG | GI2: TM | GJ2: TOF | GK2: TPG | GL2: Blank | GM2: Res | GN2: BPI | GO2: Tempo
A3: 2 | B3: ACC | C3: Duke | D3: Blue Devils | E3: 1 | F3: WIN | H3: =_xlfn.IFNA(INDEX(importBPIRkCol,MATCH(INDEX(espnMap,MATCH(C3,valCol,0)),bpiImportCol,0)+rowOffset),INDEX(importBPIRkCol,MATCH(INDEX(espnMap2,MATCH(C3,valCol,0)),bpiImportCol,0)+rowOffset)) -> 1 | I3: =IFERROR(INDEX('Net Import'!A:A,MATCH(INDEX(mapping!B:B,MATCH(C3,mapping!A:A,0),1),'Net Import'!B:B,0),1),0) -> 1 | J3: =_xlfn.IFNA(INDEX(sorRkCol,MATCH(INDEX(espnMap,MATCH(C3,valCol,0)),sorTeamCol,0)+sorRowOffset),INDEX(sorRkCol,MATCH(INDEX(espnMap2,MATCH(C3,valCol,0)),sorTeamCol,0)+sorRowOffset)) -> 3 | K3: 1 | L3: 1 | M3: =CW3+R3*1.8+IF(K3>0,K3-26,0)/2+IF(CV3>0.5,0,10)-0.5*O3-IF(F3="WIN",1,IF(F3="IN",0.5,0))-S3+IF(W3>13.5,2,0)-IF(W3<6,6-W3,0) -> -70.972 | N3: =IF(COUNTIF(H3:J3,"<50.5")>1.5,1,0) -> 1 | O3: =_xlfn.IFNA(INDEX(importBPICol,MATCH(INDEX(espnMap,MATCH(C3,valCol,0)),bpiImportCol,0)+rowOffset), INDEX(importBPICol,MATCH(INDEX(espnMap2,MATCH(C3,valCol,0)),bpiImportCol,0)+rowOffset)) -> 25.6 | P3: =INDEX(kpOff,MATCH(INDEX(kpVal,MATCH(C3,valCol,0)),kpTeam,0)) -> 5 | Q3: =INDEX(kpDef,MATCH(INDEX(kpVal,MATCH(C3,valCol,0)),kpTeam,0)) -> 1 | R3: =-1*INDEX(calculatedResVal,MATCH(C3,resValueTeamCol,0)) -> -19.24 | S3: 8 | T3: 0 | U3: =COUNTA(AW3:BK3)+COUNTA(Y3:AJ3) -> 16 | V3: =COUNTA(BL3:BX3)+COUNTA(AK3:AV3) -> 2 | W3: =COUNTA(AK3:AV3)+COUNTA(BL3:CS3) -> 2 | X3: =IF(SUM(S3:W3)>0,1,0) -> 1 | Y3: KU | Z3: ARK | AA3: FLA | AB3: MSU | AC3: LOU | AD3: SMU | AE3: CLEM | AF3: MICH | AG3: UVA | AH3: UNC | AI3: UVA | AK3: TTU | AL3: UNC | AW3: TEX | AX3: CAL | AY3: VT | AZ3: NCSU | BA3: CLEM | CT3: =H3*0.4+J3*1.2+I3*0.8 -> 4.8 | CU3: =CT3/2.4 -> 2 | CV3: =VLOOKUP(B3,'SODiv Index'!A:B,2,FALSE) -> 1 | CW3: =CU3*(10-CV3/5)/10 -> 1.96 | CX3: =INDEX('Stats import'!H:H,MATCH((INDEX(mapping!R:R,MATCH(INDEX(statsCategories,1,1),mapping!P:P,0),1)+INDEX(mapping!H:H,MATCH(C3,mapping!A:A,0),1)),'Stats import'!B:B,0),1) -> 1.61 | CY3: =INDEX('Stats import'!H:H,MATCH((INDEX(mapping!R:R,MATCH(INDEX(statsCategories,1,2),mapping!P:P,0),1)+INDEX(mapping!H:H,MATCH(C3,mapping!A:A,0),1)),'Stats import'!B:B,0),1) -> 16.9 | CZ3: =INDEX('Stats import'!H:H,MATCH((INDEX(mapping!R:R,MATCH(INDEX(statsCategories,1,3),mapping!P:P,0),1)+INDEX(mapping!H:H,MATCH(C3,mapping!A:A,0),1)),'Stats import'!B:B,0),1) -> 20.21 | DA3: =INDEX('Stats import'!H:H,MATCH((INDEX(mapping!R:R,MATCH(INDEX(statsCategories,1,4),mapping!P:P,0),1)+INDEX(mapping!H:H,MATCH(C3,mapping!A:A,0),1)),'Stats import'!B:B,0),1) -> 3.3 | DB3: =INDEX('Stats import'!H:H,MATCH((INDEX(mapping!R:R,MATCH(INDEX(statsCategories,1,5),mapping!P:P,0),1)+INDEX(mapping!H:H,MATCH(C3,mapping!A:A,0),1)),'Stats import'!B:B,0),1) -> 0.568 | DC3: =INDEX('Stats import'!H:H,MATCH((INDEX(mapping!R:R,MATCH(INDEX(statsCategories,1,6),mapping!P:P,0),1)+INDEX(mapping!H:H,MATCH(C3,mapping!A:A,0),1)),'Stats import'!B:B,0),1) -> 10.09 | DD3: =INDEX('Stats import'!H:H,MATCH((INDEX(mapping!R:R,MATCH(INDEX(statsCategories,1,7),mapping!P:P,0),1)+INDEX(mapping!H:H,MATCH(C3,mapping!A:A,0),1)),'Stats import'!B:B,0),1) -> 49 | DE3: =INDEX('Stats import'!H:H,MATCH((INDEX(mapping!R:R,MATCH(INDEX(statsCategories,1,8),mapping!P:P,0),1)+INDEX(mapping!H:H,MATCH(C3,mapping!A:A,0),1)),'Stats import'!B:B,0),1) -> 39.2 | DF3: =INDEX('Stats import'!H:H,MATCH((INDEX(mapping!R:R,MATCH(INDEX(statsCategories,1,9),mapping!P:P,0),1)+INDEX(mapping!H:H,MATCH(C3,mapping!A:A,0),1)),'Stats import'!B:B,0),1) -> 15.7 | DG3: =INDEX('Stats import'!H:H,MATCH((INDEX(mapping!R:R,MATCH(INDEX(statsCategories,1,10),mapping!P:P,0),1)+INDEX(mapping!H:H,MATCH(C3,mapping!A:A,0),1)),'Stats import'!B:B,0),1) -> 22.1 | DH3: =INDEX('Stats import'!H:H,MATCH((INDEX(mapping!R:R,MATCH(INDEX(statsCategories,1,11),mapping!P:P,0),1)+INDEX(mapping!H:H,MATCH(C3,mapping!A:A,0),1)),'Stats import'!B:B,0),1) -> 72.4 | DI3: =INDEX('Stats import'!H:H,MATCH((INDEX(mapping!R:R,MATCH(INDEX(statsCategories,1,12),mapping!P:P,0),1)+INDEX(mapping!H:H,MATCH(C3,mapping!A:A,0),1)),'Stats import'!B:B,0),1) -> 16 | DJ3: =INDEX('Stats import'!H:H,MATCH((INDEX(mapping!R:R,MATCH(INDEX(statsCategories,1,13),mapping!P:P,0),1)+INDEX(mapping!H:H,MATCH(C3,mapping!A:A,0),1)),'Stats import'!B:B,0),1) -> 10.9 | DK3: =INDEX('Stats import'!H:H,MATCH((INDEX(mapping!R:R,MATCH(INDEX(statsCategories,1,14),mapping!P:P,0),1)+INDEX(mapping!H:H,MATCH(C3,mapping!A:A,0),1)),'Stats import'!B:B,0),1) -> 27.82 | DL3: =INDEX('Stats import'!H:H,MATCH((INDEX(mapping!R:R,MATCH(INDEX(statsCategories,1,15),mapping!P:P,0),1)+INDEX(mapping!H:H,MATCH(C3,mapping!A:A,0),1)),'Stats import'!B:B,0),1) -> 12.47 | DM3: =INDEX('Stats import'!H:H,MATCH((INDEX(mapping!R:R,MATCH(INDEX(statsCategories,1,16),mapping!P:P,0),1)+INDEX(mapping!H:H,MATCH(C3,mapping!A:A,0),1)),'Stats import'!B:B,0),1) -> 40.29 | DN3: =INDEX('Stats import'!H:H,MATCH((INDEX(mapping!R:R,MATCH(INDEX(statsCategories,1,17),mapping!P:P,0),1)+INDEX(mapping!H:H,MATCH(C3,mapping!A:A,0),1)),'Stats import'!B:B,0),1) -> 63.1 | DO3: =INDEX('Stats import'!H:H,MATCH((INDEX(mapping!R:R,MATCH(INDEX(statsCategories,1,18),mapping!P:P,0),1)+INDEX(mapping!H:H,MATCH(C3,mapping!A:A,0),1)),'Stats import'!B:B,0),1) -> 19.1 | DP3: =INDEX('Stats import'!H:H,MATCH((INDEX(mapping!R:R,MATCH(INDEX(statsCategories,1,19),mapping!P:P,0),1)+INDEX(mapping!H:H,MATCH(C3,mapping!A:A,0),1)),'Stats import'!B:B,0),1) -> 82.3 | DQ3: =INDEX('Stats import'!H:H,MATCH((INDEX(mapping!R:R,MATCH(INDEX(statsCategories,1,20),mapping!P:P,0),1)+INDEX(mapping!H:H,MATCH(C3,mapping!A:A,0),1)),'Stats import'!B:B,0),1) -> 7.8 | DR3: =INDEX('Stats import'!H:H,MATCH((INDEX(mapping!R:R,MATCH(INDEX(statsCategories,1,21),mapping!P:P,0),1)+INDEX(mapping!H:H,MATCH(C3,mapping!A:A,0),1)),'Stats import'!B:B,0),1) -> 25.9 | DS3: =INDEX('Stats import'!H:H,MATCH((INDEX(mapping!R:R,MATCH(INDEX(statsCategories,1,22),mapping!P:P,0),1)+INDEX(mapping!H:H,MATCH(C3,mapping!A:A,0),1)),'Stats import'!B:B,0),1) -> 35.1 | DT3: =INDEX('Stats import'!H:H,MATCH((INDEX(mapping!R:R,MATCH(INDEX(statsCategories,1,23),mapping!P:P,0),1)+INDEX(mapping!H:H,MATCH(C3,mapping!A:A,0),1)),'Stats import'!B:B,0),1) -> 30.4 | DU3: =INDEX('Stats import'!H:H,MATCH((INDEX(mapping!R:R,MATCH(INDEX(statsCategories,1,24),mapping!P:P,0),1)+INDEX(mapping!H:H,MATCH(C3,mapping!A:A,0),1)),'Stats import'!B:B,0),1) -> 9.1 | DV3: =INDEX('Stats import'!H:H,MATCH((INDEX(mapping!R:R,MATCH(INDEX(statsCategories,1,25),mapping!P:P,0),1)+INDEX(mapping!H:H,MATCH(C3,mapping!A:A,0),1)),'Stats import'!B:B,0),1) -> 1.6 | DW3: =INDEX('Stats import'!H:H,MATCH((INDEX(mapping!R:R,MATCH(INDEX(statsCategories,1,26),mapping!P:P,0),1)+INDEX(mapping!H:H,MATCH(C3,mapping!A:A,0),1)),'Stats import'!B:B,0),1) -> 12.18 | DX3: =INDEX('Stats import'!H:H,MATCH((INDEX(mapping!R:R,MATCH(INDEX(statsCategories,1,27),mapping!P:P,0),1)+INDEX(mapping!H:H,MATCH(C3,mapping!A:A,0),1)),'Stats import'!B:B,0),1) -> 10.5 | DZ3: =R3 -> -19.24 | EA3: =-O3 -> -25.6 | EB3: =INDEX('KenPom import'!J:J,MATCH(INDEX(kpVal,MATCH(C3,valCol,0)),kpTeam,0)) -> 65.4 | EC3: =(CX3-INDEX(FK:FK,4,1))/INDEX(FK:FK,3,1) -> 0.68827365 | ED3: =(CY3-INDEX(FL:FL,4,1))/INDEX(FL:FL,3,1) -> 0.80246063 | EE3: =(CZ3-INDEX(FM:FM,4,1))/INDEX(FM:FM,3,1) -> -0.24577273 | EF3: =(DA3-INDEX(FN:FN,4,1))/INDEX(FN:FN,3,1) -> -0.45964727 | EG3: =(DB3-INDEX(FO:FO,4,1))/INDEX(FO:FO,3,1) -> 1.1009436 | EH3: =(DC3-INDEX(FP:FP,4,1))/INDEX(FP:FP,3,1) -> -0.34845678 | EI3: =(DD3-INDEX(FQ:FQ,4,1))/INDEX(FQ:FQ,3,1) -> 1.0179596 | EJ3: =(DE3-INDEX(FR:FR,4,1))/INDEX(FR:FR,3,1)*-1 -> 1.6455587 | EK3: =(DF3-INDEX(FS:FS,4,1))/INDEX(FS:FS,3,1)*-1 -> 0.90466037 | EL3: =(DG3-INDEX(FT:FT,4,1))/INDEX(FT:FT,3,1) -> 0.23218271 | EM3: =(DH3-INDEX(FU:FU,4,1))/INDEX(FU:FU,3,1) -> -0.40003716 | EN3: =(DI3-INDEX(FV:FV,4,1))/INDEX(FV:FV,3,1) -> 0.10037813 | EO3: =(DJ3-INDEX(FW:FW,4,1))/INDEX(FW:FW,3,1) -> 1.9983069 | EP3: =(DK3-INDEX(FX:FX,4,1))/INDEX(FX:FX,3,1) -> 1.2792059 | EQ3: =(DL3-INDEX(FY:FY,4,1))/INDEX(FY:FY,3,1) -> 0.59639232 | ER3: =(DM3-INDEX(FZ:FZ,4,1))/INDEX(FZ:FZ,3,1) -> 1.2278606 | ES3: =(DN3-INDEX(GA:GA,4,1))/INDEX(GA:GA,3,1)*-1 -> 1.8181231 | ET3: =(DO3-INDEX(GB:GB,4,1))/INDEX(GB:GB,3,1) -> 2.2432717 | EU3: =(DP3-INDEX(GC:GC,4,1))/INDEX(GC:GC,3,1) -> 0.32717448 | EV3: =(DQ3-INDEX(GD:GD,4,1))/INDEX(GD:GD,3,1) -> 0.5807823 | EW3: =(DR3-INDEX(GE:GE,4,1))/INDEX(GE:GE,3,1) -> 0.41018258 | EX3: =(DS3-INDEX(GF:GF,4,1))/INDEX(GF:GF,3,1) -> -0.13777714 | EY3: =(DT3-INDEX(GG:GG,4,1))/INDEX(GG:GG,3,1)*-1 -> 1.2065724 | EZ3: =(DU3-INDEX(GH:GH,4,1))/INDEX(GH:GH,3,1) -> 0.31347468 | FA3: =(DV3-INDEX(GI:GI,4,1))/INDEX(GI:GI,3,1) -> 0.12241811 | FB3: =(DW3-INDEX(GJ:GJ,4,1))/INDEX(GJ:GJ,3,1) -> 0.031547334 | FC3: =(DX3-INDEX(GK:GK,4,1))/INDEX(GK:GK,3,1)*-1 -> 0.2395513 | FD3: =(DZ3-INDEX(GM:GM,4,1))/INDEX(GM:GM,3,1)*-1 -> 2.5946378 | FE3: =(EA3-INDEX(GN:GN,4,1))/INDEX(GN:GN,3,1)*-1 -> 1.8507341 | FF3: =(EB3-INDEX(GO:GO,4,1))/INDEX(GO:GO,3,1) -> -0.93387462 | FG3: =(((DP3-DI3-3*DU3)/2)+1.5*DU3)/DB3-DR3 -> 32.462676 | FH3: =DR3/(DR3+FG3) -> 0.44377677 | FJ3: STD | FK3: =_xlfn.STDEV.S(CX:CX) -> 0.23736925 | FL3: =_xlfn.STDEV.S(CY:CY) -> 1.8879431 | FM3: =_xlfn.STDEV.S(CZ:CZ) -> 6.1586369 | FN3: =_xlfn.STDEV.S(DA:DA) -> 0.98173107 | FO3: =_xlfn.STDEV.S(DB:DB) -> 0.024649309 | FP3: =_xlfn.STDEV.S(DC:DC) -> 3.2669044 | FQ3: =_xlfn.STDEV.S(DD:DD) -> 2.0408471 | FR3: =_xlfn.STDEV.S(DE:DE) -> 2.0768023 | FS3: =_xlfn.STDEV.S(DF:DF) -> 1.5668864 | FT3: =_xlfn.STDEV.S(DG:DG) -> 2.9071932 | FU3: =_xlfn.STDEV.S(DH:DH) -> 3.0590908 | FV3: =_xlfn.STDEV.S(DI:DI) -> 2.2415241 | FW3: =_xlfn.STDEV.S(DJ:DJ) -> 3.6505904 | FX3: =_xlfn.STDEV.S(DK:DK) -> 1.8466535 | FY3: =_xlfn.STDEV.S(DL:DL) -> 1.6930969 | FZ3: =_xlfn.STDEV.S(DM:DM) -> 2.7468509 | GA3: =_xlfn.STDEV.S(DN:DN) -> 4.6235869 | GB3: =_xlfn.STDEV.S(DO:DO) -> 4.4360432 | GC3: =_xlfn.STDEV.S(DP:DP) -> 5.0431806 | GD3: =_xlfn.STDEV.S(DQ:DQ) -> 1.3365593 | GE3: =_xlfn.STDEV.S(DR:DR) -> 4.0134566 | GF3: =_xlfn.STDEV.S(DS:DS) -> 1.995977 | GG3: =_xlfn.STDEV.S(DT:DT) -> 1.7383955 | GH3: =_xlfn.STDEV.S(DU:DU) -> 1.58705 | GI3: =_xlfn.STDEV.S(DV:DV) -> 1.9298615 | GJ3: =_xlfn.STDEV.S(DW:DW) -> 1.7275628 | GK3: =_xlfn.STDEV.S(DX:DX) -> 1.0644901 | GL3: =_xlfn.STDEV.S(DY:DY) -> #DIV/0! | GM3: =_xlfn.STDEV.S(DZ:DZ) -> 9.6852132 | GN3: =_xlfn.STDEV.S(EA:EA) -> 7.77867 | GO3: =_xlfn.STDEV.S(EB:EB) -> 2.411994
